Workbook

Sheet システム要求
A1: 電池性能 要求マトリクス（MBSE用）
A2: ※「項目」列を入力すると ID（BAT-001…）が自動採番されます。行はデータ入力に応じて下方向へ追加してください。
A3: ID | B3: 項目 | C3: 中項目 | D3: ステークホルダーニーズ/システム機能 | E3: 設定の背景 | F3: ステータス | G3: 優先度 | H3: 条件 | I3: システム要求値 | J3: 考え方（根拠） | K3: 上位要求ID | L3: 検証方法 | M3: 備考 | N3: 情報元（出典資料）
A4: =IF($B4="","","BAT-"&TEXT(COUNTIF($B$4:$B4,"?*"),"000")) -> BAT-001 | B4: 電気安全性能 | C4: 全体目標（K） | D4: K-4 高電圧安全・絶縁 | N4: 20260402_解析力向上_素性・開発効率向上_V02_展開資料5.pdf / 250321_プロ検_年度まとめ.pptx / 【部長級】将来BEV_電池×システム先行開発連携.pptx
A5: =IF($B5="","","BAT-"&TEXT(COUNTIF($B$4:$B5,"?*"),"000")) -> BAT-002 | B5: 電気安全性能 | C5: 高電圧安全・絶縁 | D5: BS20 絶縁抵抗性能：高電圧回路とシャーシグラウンド間の絶縁要求 | N5: 20260402_解析力向上_素性・開発効率向上_V02_展開資料5.pdf
A6: =IF($B6="","","BAT-"&TEXT(COUNTIF($B$4:$B6,"?*"),"000")) -> BAT-003 | B6: 電気安全性能 | C6: 高電圧安全・絶縁 | D6: BS21 絶縁耐力性能：高電圧印加時の絶縁破壊耐性
A7: =IF($B7="","","BAT-"&TEXT(COUNTIF($B$4:$B7,"?*"),"000")) -> BAT-004 | B7: 電気安全性能 | C7: 高電圧安全・絶縁 | D7: BS22 高圧接触保護構造：感電防止の物理保護構造（IPXXB等）
A8: =IF($B8="","","BAT-"&TEXT(COUNTIF($B$4:$B8,"?*"),"000")) -> BAT-005 | B8: 電気安全性能 | C8: 高電圧安全・絶縁 | D8: BS23 絶縁距離性能：沿面距離・空間距離の安全基準
A9: =IF($B9="","","BAT-"&TEXT(COUNTIF($B$4:$B9,"?*"),"000")) -> BAT-006 | B9: 電気安全性能 | C9: 高電圧安全・絶縁 | D9: BS18 外部短絡安全性性能：外部短絡時の耐性と安全性
A10: BAT-007 | B10: 電気安全性能 | C10: 外部短絡 | D10: 法規(AIS-038 Rev.2)を満足させる | E10: 短絡電流によって発生する重大事象を防止するための短絡保護機能の有効性を確認する | H10: 本試験は、完成車、完全REESS、またはREESSサブシステムのいずれかを用いて実施する。 (a) 環境温度20 ± 10 ℃、またはメーカーが要請より高い温度で実施。 (b) SOCは 外部充電可能なREESS≧SOC 95% 車両内発電REESS ≧ 90% (c) すべての保護装置は作動可能な状態である。 (d) 完成車試験ではブレークアウトハーネスを接続して試験してもよい。 接続する抵抗は5 mΩ以下。 保護機能が作動し短絡電流を停止、もしくはREESS外部温度変化が2時間で4℃未満になるまで、短絡状態は1時間は継続する。 試験手順終了後、試験環境温度下で1h観察。 | I10: 試験中、REESSの電解液漏れ、破裂、ベント(開放形駆動用電池以外のREESS)、火災または爆発の証拠があってはならない。 高電圧REESSについては、試験後に測定した絶縁抵抗が100 Ω/Volt以上。 | M10: Base Reg: UN R100, GTR 20 (Phase 1) | N10: SH25-0080.pdf 6.6 / Annexure-IX-F
A11: BAT-008 | B11: 電気安全性能 | C11: 外部短絡保護 | D11: 法規(GB38031-2025)を満足させる | E11: 外部短絡保護機能を備え、短絡時の安全要求を満足する。 人体と財産の安全保護を提供するため。 2020年版から外部短絡保護の安全要求を変更。 | H11: 完全REESS試験 (a) 20℃±10℃或いはメーカーが要求より高い温度で実施。 (b) あらゆる保護設備は正常な運行状態。 (c) 短絡抵抗は、5mΩを超えない。 (d) 短絡の状態を保持し、下記のいずれかの条件に適合した場合、試験を終了。 ・試験対象の保護機能が働き、短絡電流を切断。 ・ハウジングの温度が安定した（温度変化は2h内で4℃を下回る）後、短絡を少なくとも1h維持した。 (e)試験手順終了後、試験環境温度下で1h観察。 SOC条件: 特別な規定がない限り、試験対象はすべて製造メーカーが規定した完全充電の状態でテスト を行う。(6.1.10) | I11: 漏洩、ハウジング破裂、着火或いは爆発の現象が発生してはならない。 試験後の絶縁抵抗は100Ω/V以上。交流回路がある場合、絶縁抵抗は500Ω/V以上。 | M11: セル試験: 5.1.3 / 8.1.4 / 8.1.8(急速充電300回) 車両試験: 外部短絡対象外 REESSサブシステム代用可能 (6.1.6): ・完成車要求に関わるすべての部分を含む ・電池管理システムを含めてよい ・テスト結果が電池パックまたはシステムの同条件下の安全性能を代表できることを証明すること | N11: GB 38031-2025 電動自動車用動力蓄電池安全要求 発布稿 JP.pdf / 5.2.13 / 8.2.13
A12: BAT-009 | B12: 電気安全性能 | C12: 外部短絡 | D12: 法規(KMVSS 48)を満足させる | E12: 外部短絡の条件下でREESSの安全性を確認する | H12: 本試験は、完成車、完全REESS、またはREESSサブシステムのいずれかを用いて実施する。 (a) 293K±10K (20℃±10℃) またはメーカー要請の際、さらに高い温度で実施する。 (b) SOC 外部充電可能なREESS≧ 95% 車両内発電REESS ≧ 90% (c) 試験結果に影響を与えるすべての保護装置は作動可能な状態とする。 (d) 車両試験の場合ブレイクアウトハーネスを接続し車両保護システムが作動可能な状態とする。 (e) 短絡誘発回路の抵抗は5 mΩ以下。 (f) 保護機能が作動し短絡電流を停止もしくはREESS外部温度変化が2時間で4℃未満になるまで、短絡状態は1時間は継続する (g) 試験は常温条件で1時間観察後、終了 (Detail KMVSS 48.7) | I12: 試験中、試験対象装置に破裂、電解液漏れ、ベンティング、火災または爆発がないこと。 漏れやベントの証拠は分解せず目視で確認。 試験後、測定した絶縁抵抗は100Ω/V以上。 | N12: DK048.pdf [Table 1] No. 48 / 48.5.2 Procedures for SOC adjustment, 48.7.4 Short circuit test
A13: BAT-010 | B13: 電気安全性能 | C13: 外部短絡 | D13: 法規(FMVSS305a)を満足させる | E13: 通常運転時および衝突中・衝突後に有害な感電、火災、爆発、ガス放出から保護する。 | H13: 車両レベル試験、初期SOCを90～95％、常温環境 (a) REESSにブレークアウトハーネスを接続する。 (b) REESS温度の変化を監視するため、REESS外側ケーシングに温度プローブを接続 （温度測定は、REESSの制御モジュールと通信することで得られる場合もある） (c) REESSの作動を管理する車両制御装置へ電力を供給する車両スイッチまたは装置を作動位置に設定する。 (d) 短絡接触器を開位置としてブレークアウトハーネスに接続する。 外部短絡を発生させる装置（短絡接触器およびブレークアウトハーネス）の総抵抗は2～5 mΩ (e) 短絡接触器を閉じ、短絡開始 (f) 短絡状態は短絡電流が止まるか短絡開始から2時間以内にREESSの温度勾配が4℃未満になる (h)短絡電流停止後、車両を1時間観察 (FMVSS305a / S12.5) | I13: (a) 試験中、車両を分解しない目視検査により確認したREESSの電解液漏れ、破裂、ベント、火災または爆発の証拠があってはならない。 (b) 試験後に測定した高電圧源の絶縁抵抗は、本基準のS7.2に従って決定した場合、100 ohms/volt未満であってはならない。 (FMVSS305a / S11.1) | M13: 短絡抵抗は2〜5mΩと下限あり。UN R100・GB38031と異なり温度安定後の1h継続なし | N13: FMVSS305a / S11.1, S12.5 SH25-0018
A14: BAT-011 | B14: 電気安全性能 | C14: 外部短絡 | D14: 法規(UN-R-100)を満足させる | E14: 短絡保護性能を検証すること。 外部短絡電流によるREESSのさらなる重大事象を防ぐこと（UN-R-100 附則9F） | H14: 完全REESSまたは電池および電気結線を含む関連するREESSサブシステムのいずれかを用いて実施する。 REESS サブシステムを選択した場合、テスト対象装置は完全 REESS の公称電圧を供給できるものとする。 (a) 周囲温度20 ± 10 ℃、またはメーカーの要請より高い温度で実施。 (b) SOC BEV/PHEV：95%以上／HEV：90%以上。 (c) すべての保護装置は作動可能。 (d)接続する抵抗は5 mΩ以下とする。 (e)保護機能が作動し短絡電流を停止、もしくはケーシング上温度変化が安定してから2時間で4℃未満になるまで、短絡状態は1時間は継続する (f)試験手順終了後、試験環境温度下で1h観察。(UN-R-100 附則9 - 付録2 / 附則9F) | I14: 以下の証拠がないものとする。(UN-R-100 6.6 外部短絡保護) (a) 電解液漏れ、(b) 破裂（高電圧REESSに限り適用する）、(c) ベント、(d) 火炎、(e) 爆発。 電解液漏れの証拠は、テスト対象装置のいかなる部品も分解せず、目視検査によって検証する 高電圧REESSについては、テスト後に測定した絶縁抵抗が100 Ω／V以上とする。 | N14: UN No.100 5 / 6.6 / 附則9F
A15: BAT-012 | B15: 電気安全性能 | C15: 外部短絡保護 | D15: 法規(SASO + GSO ECE 100)を満足させる | E15: 電気自動車やその部品の安全面を確保し、バッテリーからの電気漏れやバッテリー部品の乗客室への漏れによって起こりうる事故、死亡、感電の可能性を最小限にすること(SASO Annex2) | H15: 完全REESSまたは電池および電気結線を含む関連するREESSサブシステムのいずれかを用いて実施する。 REESS サブシステムを選択した場合、テスト対象装置は完全 REESS の公称電圧を供給できるものとする。 (a) 周囲温度20 ± 10 ℃、またはメーカーの要請より高い温度で実施。 (b) SOC BEV/PHEV：95%以上／HEV：90%以上。 (c) すべての保護装置は作動可能。 (d)接続する抵抗は5 mΩ以下とする。 (e)保護機能が作動し短絡電流を停止、もしくはケーシング上温度変化が安定してから2時間で4℃未満になるまで、短絡状態は1時間は継続する (f)試験手順終了後、試験環境温度下で1h観察。(UN-R-100 附則9 - 付録2 / 附則9F) | I15: 以下の証拠がないものとする。(UN-R-100 6.6 外部短絡保護) (a) 電解液漏れ、(b) 破裂（高電圧REESSに限り適用する）、(c) ベント、(d) 火炎、(e) 爆発。 電解液漏れの証拠は、テスト対象装置のいかなる部品も分解せず、目視検査によって検証する 高電圧REESSについては、テスト後に測定した絶縁抵抗が100 Ω／V以上とする。 | M15: SASOは独自試験なし UN R100(=GSO ECE 100)/FMVSS 305aを参照する構造 | N15: SASO法規原文(英語)_2026.pdf, GSO法規原文(日本語訳)_2026.pdf
A16: =IF($B16="","","BAT-"&TEXT(COUNTIF($B$4:$B16,"?*"),"000")) -> BAT-013 | B16: 電気安全性能 | C16: 外部短絡保護 | D16: 法規(UAE.S + GSO ECE 100)を満足させる | E16: 駆動用電池からの電解液漏れ、駆動用電池システム部品の乗員室への侵入、および感電に起因して、衝突時・感電時に発生する死亡および傷害を低減するもの | H16: 完全REESSまたは電池および電気結線を含む関連するREESSサブシステムのいずれかを用いて実施する。 REESS サブシステムを選択した場合、テスト対象装置は完全 REESS の公称電圧を供給できるものとする。 (a) 周囲温度20 ± 10 ℃、またはメーカーの要請より高い温度で実施。 (b) SOC BEV/PHEV：95%以上／HEV：90%以上。 (c) すべての保護装置は作動可能。 (d)接続する抵抗は5 mΩ以下とする。 (e)保護機能が作動し短絡電流を停止、もしくはケーシング上温度変化が安定してから2時間で4℃未満になるまで、短絡状態は1時間は継続する (f)試験手順終了後、試験環境温度下で1h観察。(UN-R-100 附則9 - 付録2 / 附則9F) | I16: 以下の証拠がないものとする。(UN-R-100 6.6 外部短絡保護) (a) 電解液漏れ、(b) 破裂（高電圧REESSに限り適用する）、(c) ベント、(d) 火炎、(e) 爆発。 電解液漏れの証拠は、テスト対象装置のいかなる部品も分解せず、目視検査によって検証する 高電圧REESSについては、テスト後に測定した絶縁抵抗が100 Ω／V以上とする。 | M16: UAEは独自試験なし UN R100(=GSO ECE 100)/FMVSS 305aを参照する構造 | N16: UAE法規原文(英語)_2026.pdf, GSO法規原文(日本語訳)_2026.pdf
A17: =IF($B17="","","BAT-"&TEXT(COUNTIF($B$4:$B17,"?*"),"000")) -> BAT-014 | B17: 電気安全性能 | D17: QCVN 09:2024を満足させる | E17: ベトナム向け型式認証（VR：Vietnam Register）への適合のため。 短絡電流によって発生する重大事象を防止するための短絡保護機能の有効性を確認する。 | H17: 完全REESSまたは電池および電気結線を含む関連するREESSサブシステムのいずれかを用いて実施する。 REESS サブシステムを選択した場合、テスト対象装置は完全 REESS の公称電圧を供給できるものとする。 (a) 周囲温度20 ± 10 ℃、またはメーカーの要請より高い温度で実施。 (b) SOC BEV/PHEV：95%以上／HEV：90%以上。 (c) すべての保護装置は作動可能。 (d)接続する抵抗は5 mΩ以下とする。 (e)保護機能が作動し短絡電流を停止、もしくはケーシング上温度変化が安定してから2時間で4℃未満になるまで、短絡状態は1時間は継続する (f)試験手順終了後、試験環境温度下で1h観察。(UN-R-100 附則9 - 付録2 / 附則9F) | I17: 以下の証拠がないものとする。(UN-R-100 6.6 外部短絡保護) (a) 電解液漏れ、(b) 破裂（高電圧REESSに限り適用する）、(c) ベント、(d) 火炎、(e) 爆発。 電解液漏れの証拠は、テスト対象装置のいかなる部品も分解せず、目視検査によって検証する 高電圧REESSについては、テスト後に測定した絶縁抵抗が100 Ω／V以上とする。 | M17: QCVN独自の外部短絡試験・判定値は無く、2.34.1.4でUN R100 第2部を全面参照する構造 | N17: QCVN 09:2024/BGTVT 2.34.1.4
A18: =IF($B18="","","BAT-"&TEXT(COUNTIF($B$4:$B18,"?*"),"000")) -> BAT-015 | B18: 電気安全性能 | C18: 外部短絡保護 | D18: ISO 6469-1を満たす RESSは動作状態での外部短絡に対し、導体の耐短絡電流定格または過電流保護によって安全性能を提供する。 | E18: 短絡電流による導体損傷および危険事象を防止するため。 | H18: 試験体 (DUT)：RESS または RESS サブシステムに適用(6.1.1) 顧客とサプライヤが合意した通常運用時の最大SOCに設定(6.1.4) RESS サブシステムを試験する場合は、設計意図どおりの過電流保護を試験体に含めること。 外部短絡の接続抵抗は 5 mΩ 以下として試験を実施する。 次のいずれかを満たした時点で試験を終了する。 ・短絡保護機能が短絡電流を遮断したとき。 ・1 時間の期間内で温度変化が 4 K 未満となったとき。 ・試験体に内部温度計測が存在し動作している場合はそれを用い、ない場合は筐体温度を計測する。 試験は、顧客とサプライヤの合意により、6.1.4 に示す周囲温度より高い温度で実施してもよい。 試験後観察期間を1時間とする(6.1.1) | I18: 漏えいなし／1秒超の連続炎なし(目視)／破損なし(ISO 20653)／爆発なし(目視,飛散物検知)(4.2 / 6.1.6) 電解液漏えいの確認は、目視、リトマス試験紙、流体の化学分析のいずれか 電圧クラスB2は試験・観察期間の終了後、下記の絶縁抵抗維持(4.2 / 6.1.6) 直流回路のみを含む場合： 100 Ω/V 交流回路を含み、ISO 6469-3 に適合する追加 AC 保護を有する場合： 100 Ω/V 交流回路を含み、ISO 6469-3 に適合する追加 AC 保護を有しない場合： 500 Ω/V (5.4.1) (a) RESS の活線導体の断面積は、RESS の最大短絡電流に対する耐短絡電流定格 (I2t) を有すること。 (b) RESS の活線導体の断面積に応じた過電流保護を設けること。当該過電流保護は短絡電流を開放できる能力 を有すること。(5.4.3) | M18: DUT (Device Under Test): RESSまたはRESSサブシステム | N18: ISO6469-1_Japanese.pdf 4.2 一般的な安全要求事項 / 5.4.1 絶縁抵抗 / 5.4.3 短絡保護 / 6.1 一般試験条件 / 6.5.1 短絡
A19: =IF($B19="","","BAT-"&TEXT(COUNTIF($B$4:$B19,"?*"),"000")) -> BAT-016 | B19: 電気安全性能 | D19: 輸送法規 UN38.3を満たす | E19: 輸送時における外部短絡条件下でのセル／電池の安全性検証 | H19: 温度測定点：セル又は電池の外装ケース ・測定温度が均一に安定した57±4℃に達するまで加熱する ・加熱時間は寸法・設計に依存するため評価し文書化する。 （評価不能な場合、暴露時間は小型セル・小型電池 6時間以上／大型セル・大型電池 12時間以上とする） ・配線含む外部総接続抵抗は0.1Ω未満 ・短絡状態は外装ケース温度が57±4℃に復帰後１時間以上継続する。 (大型バッテリは観測された最大上昇温度分の半分まで低下しその値を下回った状態で1時間継続) ・短絡フェーズ、冷却フェーズでは周囲温度以上で実施する | I19: セル及び電池は測定温度が170℃を超えず、かつ試験中および試験後6時間以内に分解、ラプチャー、発火がないこと | N19: ST/SG/AC.10/11/Rev.8 38.3.4.5 Test T.5: External short circuit ST/SG/AC.10/11/Rev.8-Amend1 38.3.4.5.2 / 38.3.4.5.3
A20: =IF($B20="","","BAT-"&TEXT(COUNTIF($B$4:$B20,"?*"),"000")) -> BAT-017 | B20: 電気安全性能 | D20: TSW 1310 外部短絡 安全性評価 | E20: 外部短絡時の電池パックの挙動を確認する / 安全性を評価する | H20: 短絡させる回路の下流側の電気抵抗値は3mΩ以下(5.1項) 電池温度：使用温度の上限61+3℃と下限温度-30-3℃ 終了条件： ・回路遮断（ヒューズ溶断） ・SMRが遮断した場合 ・電池電圧が下限電圧に到達した場合 | I20: ・ヒューズまたはSMRで安全に高電圧を遮断できること ・漏液、破裂、発火、爆発がないこと ・短絡時の突入電流が定格遮断電流値の設計保証以下であること ・CID設定のあるLiセルはCID作動がないこと ・絶縁抵抗100Ω/V以上 ・セル圧力弁の作動がないこと | N20: TSW1310G / TSW1310G-1
A21: =IF($B21="","","BAT-"&TEXT(COUNTIF($B$4:$B21,"?*"),"000")) -> BAT-018 | B21: 熱・温度性能 | C21: 熱衝撃 | N21: 20260402_解析力向上_素性・開発効率向上_V02_展開資料5.pdf
A22: =IF($B22="","","BAT-"&TEXT(COUNTIF($B$4:$B22,"?*"),"000")) -> BAT-019 | B22: 熱・温度性能 | C22: 基本電気・熱特性・寿命 | D22: BS25 冷却温度制御条件：セル充放電時の許容温度範囲
A23: =IF($B23="","","BAT-"&TEXT(COUNTIF($B$4:$B23,"?*"),"000")) -> BAT-020 | B23: 熱・温度性能 | C23: 基本電気・熱特性・寿命 | D23: BS27 動作温度限界性能：極低温・極高温下のシステム出力動作限界
A24: =IF($B24="","","BAT-"&TEXT(COUNTIF($B$4:$B24,"?*"),"000")) -> BAT-021 | B24: 熱・温度性能 | C24: 基本電気・熱特性・寿命 | D24: BS28 環境動作温度・湿度範囲：車両運用の外的環境仕様
A25: =IF($B25="","","BAT-"&TEXT(COUNTIF($B$4:$B25,"?*"),"000")) -> BAT-022 | B25: 振動・衝撃耐久性能 | C25: 全体目標（K） | D25: K-3 強度・衝突安全 | N25: 20260402_解析力向上_素性・開発効率向上_V02_展開資料5.pdf / 260528_素性効率向上検討会_BVPx次世代コンセプト_期初計画.pptx
A26: =IF($B26="","","BAT-"&TEXT(COUNTIF($B$4:$B26,"?*"),"000")) -> BAT-023 | B26: 振動・衝撃耐久性能 | C26: 強度・機械的防護 | D26: BS11 耐久信頼性性能：実働応力・悪路・高速波状路・突起乗り越し等の構造耐久
A27: =IF($B27="","","BAT-"&TEXT(COUNTIF($B$4:$B27,"?*"),"000")) -> BAT-024 | B27: 振動・衝撃耐久性能 | C27: 強度・機械的防護 | D27: BS12 振動適合：走行振動を模擬した規格適合試験要求
A28: =IF($B28="","","BAT-"&TEXT(COUNTIF($B$4:$B28,"?*"),"000")) -> BAT-025 | B28: 圧壊・機械破壊性能 | C28: 強度・機械的防護 | D28: BS16 圧壊安全性性能：圧壊試験における圧壊耐性と安全性 | N28: 20260402_解析力向上_素性・開発効率向上_V02_展開資料5.pdf
A29: =IF($B29="","","BAT-"&TEXT(COUNTIF($B$4:$B29,"?*"),"000")) -> BAT-026 | B29: 圧壊・機械破壊性能 | C29: 強度・機械的防護 | D29: BS14 路面・落下物干渉防護：外部突起干渉・衝突に対する物理防護
A30: =IF($B30="","","BAT-"&TEXT(COUNTIF($B$4:$B30,"?*"),"000")) -> BAT-027 | B30: 圧壊・機械破壊性能 | C30: 強度・機械的防護 | D30: BS19 底部機械防護性能：電池パック底部の物理防護・耐荷重
A31: =IF($B31="","","BAT-"&TEXT(COUNTIF($B$4:$B31,"?*"),"000")) -> BAT-028 | B31: 衝突安全性能 | C31: 側突 | H31: 現行 32 km/h ／ 将来 40 km/h | N31: 20260402_解析力向上_素性・開発効率向上_V02_展開資料5.pdf / 260317_内山田相談役報告_次世代電池パック開発（普及版）.pptx / 250321_プロ検_年度まとめ.pptx
A32: =IF($B32="","","BAT-"&TEXT(COUNTIF($B$4:$B32,"?*"),"000")) -> BAT-029 | B32: 衝突安全性能 | C32: ポール側突
A33: =IF($B33="","","BAT-"&TEXT(COUNTIF($B$4:$B33,"?*"),"000")) -> BAT-030 | B33: 衝突安全性能 | C33: 強度・機械的防護 | D33: BS15 衝突安全性性能：衝突時のエネルギー吸収量・セル保護判定 | H33: 2セルごと停止狙い（設計方針）
A34: =IF($B34="","","BAT-"&TEXT(COUNTIF($B$4:$B34,"?*"),"000")) -> BAT-031 | B34: 熱拡散安全性能 | C34: 熱拡散 | D34: 法規(UN-R-100/05)を満足させる | E34: REESS内の電池において強制的な熱暴走が引き起こされる場合に、車両内の乗員の安全を確保する（UN 附則9K 1項）。単電池の熱暴走をきっかけとした熱伝播による危険な環境に車両乗員が曝露されないこと（UN 6.15）。 | F34: 完了 | H34: 車両対象テスト、又は構成部品対象テスト（REESS若しくはREESSサブシステム）のいずれかを実施（カットボディでTMCは実施） 外部ヒーターによる加熱 最高動作温度より少なくとも100 ℃高い温度 熱暴走確認時点、またはヒーターへの総エネルギー入力が起点電池エネルギーの20％で停止 起点電池面積の20%を超えない[^3]表1：ヒーター装置選択ガイド：目標パラメータ 厚み ＜5 mm 加熱率 ≧15 ℃/s 最高温度 最高動作温度より少なくとも100 ℃高い温度[[3] | I34: **危険状況の禁止**：警告信号から**5分間**、以下が発生しないこと[^3] - (a) 火災 - (b) 爆発 - (c) 客室内へのスモーク放出 | J34: 法規に準拠 | N34: UN-R-100/05 附則9K - 付録1
A35: =IF($B35="","","BAT-"&TEXT(COUNTIF($B$4:$B35,"?*"),"000")) -> BAT-032 | B35: 熱拡散安全性能 | D35: 法規(UN-R-100/05)を満足させる | E35: REESS内の電池において強制的な熱暴走が引き起こされる場合に、車両内の乗員の安全を確保する（UN 附則9K 1項）。単電池の熱暴走をきっかけとした熱伝播による危険な環境に車両乗員が曝露されないこと（UN 6.15）。 | H35: ↑ | I35: **2時間非伝播による適合**：起点電池の熱暴走から**2時間**熱伝播が観察されなければ、要件を満たすとみなす[^3] | J35: 法規に準拠
A36: =IF($B36="","","BAT-"&TEXT(COUNTIF($B$4:$B36,"?*"),"000")) -> BAT-033 | B36: 熱拡散安全性能 | D36: 法規(UN-R-100/05)を満足させる | E36: REESS内の電池において強制的な熱暴走が引き起こされる場合に、車両内の乗員の安全を確保する（UN 附則9K 1項）。単電池の熱暴走をきっかけとした熱伝播による危険な環境に車両乗員が曝露されないこと（UN 6.15）。 | H36: ↑ | I36: **熱暴走未誘発による適合**：選択トリガー法で熱暴走が誘発されず、同一手順の繰返しまたは電池レベル試験で確認された場合も適合[^3] | J36: 法規に準拠
A37: =IF($B37="","","BAT-"&TEXT(COUNTIF($B$4:$B37,"?*"),"000")) -> BAT-034 | B37: 熱拡散安全性能 | D37: 法規(UN-R-100/05)を満足させる | E37: REESS内の電池において強制的な熱暴走が引き起こされる場合に、車両内の乗員の安全を確保する（UN 附則9K 1項）。単電池の熱暴走をきっかけとした熱伝播による危険な環境に車両乗員が曝露されないこと（UN 6.15）。 | H37: ↑ | I37: 外部加熱（付録1）特有の終了条件として、ヒーターリレー開放後**1時間**の観察で起点電池が熱暴走しなければ適合 | J37: 法規に準拠
A38: =IF($B38="","","BAT-"&TEXT(COUNTIF($B$4:$B38,"?*"),"000")) -> BAT-035 | B38: 熱拡散安全性能 | C38: 熱拡散 | D38: 法規(GB38031-2025)を満足させる | E38: 電池パック又はシステム又は車両について、熱拡散における乗員保護分析と検証を行う（GB 5.2.7 b／8.2.7.2）。単一の電池が内部短絡により熱制御不能になった後、発火・爆発せず、5min以内に熱事件警報信号を提供し乗員室に危険がないこと（GB 付録C C.1） | H38: 試験形態：電池パック 電気エネルギー別に規定（例：E≥800Whで>600W）表C.2 加熱装置の出力選択 トリガー対象の電気エネルギー EWh／加熱装置の最大出力W E<100 30～300 100≤E<400 300～1000 400≤E<800 300～2000 E≥800 >600[] 熱暴走発生時、または監視点300℃到達時[^2] 加熱装置の反対側（熱伝導から遠い側） 開始温度：セル22℃±5℃に調整[^5] 試験終了条件：すべての監視測定点の温度が60℃を超えず、かつ観察時間が2時間以上であること | I38: **発火・爆発**：発火しない、爆発しないこと | J38: 法規に準拠 | N38: GB38031-2025 付録 C.5.3
A39: =IF($B39="","","BAT-"&TEXT(COUNTIF($B$4:$B39,"?*"),"000")) -> BAT-036 | B39: 熱拡散安全性能 | C39: 熱拡散 | D39: 法規(GB38031-2025)を満足させる | E39: 電池パック又はシステム又は車両について、熱拡散における乗員保護分析と検証を行う（GB 5.2.7 b／8.2.7.2）。単一の電池が内部短絡により熱制御不能になった後、発火・爆発せず、5min以内に熱事件警報信号を提供し乗員室に危険がないこと（GB 付録C C.1） | H39: ↑ | I39: **警報時間**：熱事件警報信号を提供し、発信時間はセル熱暴走触発から**5分以内**であること | N39: GB38031-2025 付録 C.5.3
A40: =IF($B40="","","BAT-"&TEXT(COUNTIF($B$4:$B40,"?*"),"000")) -> BAT-037 | B40: 熱拡散安全性能 | C40: 熱拡散 | D40: 法規(GB38031-2025)を満足させる | E40: 電池パック又はシステム又は車両について、熱拡散における乗員保護分析と検証を行う（GB 5.2.7 b／8.2.7.2）。単一の電池が内部短絡により熱制御不能になった後、発火・爆発せず、5min以内に熱事件警報信号を提供し乗員室に危険がないこと（GB 付録C C.1） | H40: ↑ | I40: **煙（パック・システムレベル）**：警報信号の前後5分以内に、煙が乗員室に危害がないことの技術説明文書を提供 **煙（車両レベル）**：警報信号の前後5分以内に、煙が乗員室に入らないこと | N40: GB38031-2025 付録 C.5.3
...

Sheet 熱拡散防止サブシステム要求
L1: 部品
B2: 基本指針 | C2: Any positionでの成立 | BA2: 主な考え方
C3: 単セル発煙に抑える | BA3: MtoP、CtoPで同じ挙動を示すと思われる点を測定し同値であることを証明し、過去知見が使えることを確認する。これ、結構重要。
B4: 定量化できるが部品設計側で定義する | D4: 一文一要求のため、複数文作成しています。 | G4: 森記載 | BA4: CtoPで変化のある部分（実施済みのDRBFMでの変化点確認）、バンド拘束がケース拘束になる部分、接着剤でRF固定とするところ、拘束部品の熱影響の変化、端セルの隣が拘束プレートでなく薄板鉄板/樹脂プレートになっている点（これは優先度低い）を見ていく。
B5: システム側で定量値にする | D5: <対象部品> = 右記●がついている部品が関係しています。 | L5: 高橋SN | M5: 長野SN | N5: 長野SN | O5: 大平SK | P5: 金子SN | R5: 伊部SN | S5: 伊部SN | T5: 伊部SN | U5: 長野SN | V5: 長野SN | W5: 大平SK、浦上SN | AF5: 大平SK | AG5: 大平SK | AI5: 金子SN | AJ5: 加茂SK | AK5: 金子SN | AN5: 大平SK、浦上SN | AO5: 金子SN | AP5: 加茂SK | AQ5: 大平SN | AR5: 田口SK | AS5: 田口SK | AT5: 田口SK
A7: ID | B7: 項目 | C7: ステークホルダーニーズ/システム機能 | D7: システム要求値 | E7: 設定の背景 | F7: ステータス | G7: 机上目途付けができているか | H7: パック試験で予測のためのデータが取れるか(CTPパックの必要性) | I7: 判断手法の有無(机上、CAE、単品要素試験、パック試験) | J7: 4号機仕様で確認できるか | K7: 根拠 | L7: セル間断熱材 | M7: エンドプレート | N7: 拘束 | O7: 絶縁カバー | P7: パックシール材 | Q7: 低圧/高圧パックI/Fシール材 | R7: アッパー断熱 | S7: 排煙バルブ | T7: 呼吸膜 | U7: ロアケース | V7: アッパーケース | W7: MOD間バスバ | X7: セル | Y7: セルフィルム | Z7: J/B | AA7: SBM | AB7: PNコネクタ | AC7: 低圧コネクタ | AD7: 高圧ヒューズ | AE7: ECU | AF7: BBM | AG7: BBMコネクタ | AH7: コネクタブロック | AI7: コネクタブロックシール材 | AJ7: 冷却器 | AK7: 熱伝導材 | AL7: 排煙サーミスタ | AM7: フェライトコア | AN7: 総±バスバー | AO7: 構造用接着剤(セル接着剤) | AP7: スペーサー | AQ7: W/H | AR7: 端子台 | AS7: PN絶縁板 | AT7: 端絶縁板 | AU7: ID | AV7: 大項目 | AW7: ステークホルダーニーズ/システム機能 | AX7: 備考 | AY7: 情報元（出典資料） | BA7: 原嶋メモ
A8: =IF($B8="","","BATs-"&TEXT(COUNTIF($B8:$B$8,"?*"),"000")) -> BATs-001 | B8: 熱拡散安全性能 | C8: 合わせ面からの漏煙を防止する | D8: 熱拡散試験中、<対象部品>ではセル開弁圧力によるシール部発生引張荷重よりもシール部引張強度は高くなければならない。 熱拡散試験中、排煙バルブの開弁圧力は熱拡散発生圧力よりも小さくなければならない。 | E8: 熱拡散機能主査DR チェックポイント集より | F8: 完了 | G8: 未検討？ 45PLの内圧と余剰空間の差から、シール性を確認。 余剰空間45PL ***L→今回***L 計算必要 その後、最大内圧とシール保証圧の安全率を計算 | H8: ダミーセルがあるが、影響しないか。 | I8: 机上 内圧計算シートを使用(横谷さんのエクセル) 4号機試験にはパック内に圧力センサを入れる 圧力解放閾値と流量の規定が必要 | P8: ● | Q8: ● | S8: ● | T8: ● | U8: ● | V8: ● | X8: ● | AB8: ● | AH8: ● | AI8: ● | AU8: =IF($B8="","","BATs-"&TEXT(COUNTIF($B8:$B$8,"?*"),"000")) -> BATs-001 | AV8: 熱拡散安全性能 | AW8: 合わせ面からの漏煙を防止する | BA8: 号口と同じシール材なら合わせ面の温度と圧力で決まる。 セル単体の瞬間的な発熱量が何に起因して変わるか不明なので、現時点、ここは議論できず。知るための方法を総研＋単品評価で確認予定。 圧力は、下記の過圧を逃がすで議論。
A9: =IF($B9="","","BATs-"&TEXT(COUNTIF($B$8:$B9,"?*"),"000")) -> BATs-002 | B9: 熱拡散安全性能 | C9: 過圧を逃がす | D9: 熱拡散試験中、排煙バルブは単セルから発生する流量と電池パックの余剰体積により決まる圧力で開弁しなければならない。 | E9: 熱拡散機能主査DR チェックポイント集より | F9: 完了 | G9: 未検討？ 45PLの内圧と余剰空間の差から、内圧見積もりと圧力解放弁の開弁圧を比較。 | I9: ↑ | P9: ● | S9: ● | T9: ● | U9: ● | V9: ● | X9: ● | AU9: =IF($B9="","","BATs-"&TEXT(COUNTIF($B$8:$B9,"?*"),"000")) -> BATs-002 | AV9: 熱拡散安全性能 | AW9: 過圧を逃がす | BA9: CtoPでの変化は、セルへの拘束荷重と余剰空間。 余剰空間は算出してください。多少の差であれば現状把握と実測確認でよい？ 拘束荷重は、初期設計値に対し、発煙後の時系列的な変化をMTOPと比較したい。
A10: =IF($B10="","","BATs-"&TEXT(COUNTIF($B$8:$B10,"?*"),"000")) -> BATs-003 | B10: 熱拡散安全性能 | C10: デブリ・溶融金属によるブリッジ（短絡）を防止する | D10: 熱拡散試験後、<対象部品>は絶縁抵抗を100MΩ以上に維持しなければならない | E10: 熱拡散機能主査DR チェックポイント集より | F10: 完了 | G10: ＜絶縁カバー＞ ミニモ試験にて絶縁カバー上の温度推定、セル噴出温度850度予想で400℃前後の見込み。単品評価では間違いなく〇レベル。絶縁カバー裏の温度予測ができていない ＜MOD間バスバ、総±バスバー＞ 700℃×30min後の絶縁確保済み。 ＜PN絶縁板＞ ミニモ試験にて絶縁板表面温度は450℃程度であり、TaG試験でもマイカ板同等の性能であった為、耐熱は○見込み。ただし噴出したデブリ量がPN絶縁板部にどこまで堆積するか不明。 またセル側面や底面からの破裂があった場合にどこまでの耐熱が必要になるかの確認が必要。 ＜UPR断熱材＞ 単品T&G試験(※課題あり)にて、45PL以上の実力を確認済み。 | H10: ＜絶縁カバー＞ ミニモとパック試験で、噴出物挙動、ガス温度、噴出物温度が違うと予想しており、机上予測が困難で、今後ミニモ試験での代用ができるかを検討したいため、絶縁カバー周辺の温度×時間データが必要。あればWhatif分析で推測予定。 ＜MOD間バスバ、総±バスバー＞ 絶縁カバーと同じ ＜PN絶縁板＞ 絶縁カバーと同様にミニモとパック試験での違いを明確にするため、PN絶縁板周辺温度×時間データとデブリ堆積量とデブリから受熱する熱エネルギーを測定したい。 ＜UPR断熱材＞ UPR断熱材裏の測温 | I10: 現状無い状態。 絶縁カバー、モジュール間バスバーの温度のストレスの定義方法 デブリの大きさ、量、飛散状況の見積もりが必要。 アルミ溶質によるセル間短絡は、アルミの導電率で計算が必要 T&G試験はあるが、内容物の質量,粒径,速度とどこまで一致しているかは不明なのが実情⇒単セル評価にて定量化を要検討 | K10: 総電圧：560 V 漏れ電流：5.6 μA 発熱量：3.14 mW 100MΩであれば発熱量は無視できるレベルと判断 | O10: ● | R10: ● | U10: ● | V10: ● | W10: ● | X10: ● | Z10: ● | AA10: ● | AD10: ● | AG10: ● | AN10: ● | AQ10: ● | AR10: ● | AS10: ● | AU10: =IF($B10="","","BATs-"&TEXT(COUNTIF($B$8:$B10,"?*"),"000")) -> BATs-003 | AV10: 熱拡散安全性能 | AW10: デブリ・溶融金属によるブリッジ（短絡）を防止する | BA10: デブリ飛散予測技術は、未確立？ Assyでは、CtoP構造、排煙経路から傾向把握。 別ラインで単品セルで拘束荷重/SOC/他何がある？？を振って、N数稼いで傾向を見る。 防御構造の設計最悪値を明示すること。
A11: =IF($B11="","","BATs-"&TEXT(COUNTIF($B$8:$B11,"?*"),"000")) -> BATs-004 | B11: 熱拡散安全性能 | C11: デブリ・溶融金属によるブリッジ（短絡）を防止する | D11: ・熱拡散試験後、<対象部品>では活電部とアッパー、PN間が絶縁材で保護されていなければならない。ただし、GNDとセルの絶縁担保は除く。 ・熱拡散試験後、活電部に絶縁保護材がある場合、<対象部品>の耐熱要件を確認し、設定要否を判断すること | E11: 熱拡散機能主査DR チェックポイント集より | F11: 完了 | G11: ＜絶縁カバー＞ 活電部カバー済み、ただし、MOD間バスバと絶縁カバーのラップ量がﾂﾗｲﾁ設定のため評価にて確認したい。ただし、インプットが変わっても推定できるか未検討 ＜MOD間バスバ＞ 700℃×30min後の絶縁確保済み。 | H11: ＜絶縁カバー＞ 噴出物の挙動、圧力による変形で活電部が露出しないか。圧力値・噴出物量が変わった際の予測ができるか不明 ＜MOD間バスバ＞ 絶縁カバーと同じ | I11: ↑ | K11: アッパーと活電部間でリークさせない MOD間バスバ間でリークさせない ※高耐熱で保護されている箇所除く | O11: ● | R11: ● | U11: ● | V11: ● | W11: ● | X11: ● | Z11: ● | AA11: ● | AD11: ● | AG11: ● | AN11: ● | AQ11: ● | AR11: ● | AS11: ● | AU11: =IF($B11="","","BATs-"&TEXT(COUNTIF($B$8:$B11,"?*"),"000")) -> BATs-004 | AV11: 熱拡散安全性能 | AW11: デブリ・溶融金属によるブリッジ（短絡）を防止する | BA11: 同上でよい？？
A12: =IF($B12="","","BATs-"&TEXT(COUNTIF($B$8:$B12,"?*"),"000")) -> BATs-005 | B12: 熱拡散安全性能 | C12: 脱落・剥離・破損なく形状を保持する | D12: 熱拡散試験中、<対象部品>は短絡、熱連鎖を引き起こす状態変化を生じてはならない。 | E12: 熱拡散機能主査DR チェックポイント集より | F12: 完了 | G12: ＜絶縁カバー＞ ミニモ試験結果より、単層構造に変更。ただし、ストレングス、ストレスの把握手段がなく机上目途が立っていない ＜PN絶縁板＞ セル熱暴走時の温度×圧力での破損懸念あり。単品熱プレス試験(800℃×260s)で形状保持できることを確認。 ＜セル間断熱材＞ 800℃ヒートプレス試験にて形状保持を確認 <UPR断熱材> T&G試験(※課題あり)にて45PL以上のサイクル数を確認 ＜熱伝導材＞ 100℃付近の熱伝導率未測定 ＜冷却器＞ 冷却プレート用接着剤は120℃までは耐熱性あり、高温接着強度は未測定 | H12: ＜絶縁カバー＞ 無し ミニモ試験で代替評価できると推測 ＜PN絶縁板＞ ミニモ試験で代用できると推測できるが、拘束荷重(面圧分布?）がミニモとパックでの違いがないかは確認したい ＜セル間断熱材＞ トリガーセル,隣接セルの腹面熱電対添付。 ＜UPR断熱材＞ UPR断熱材裏面温度測定 | K12: 熱暴走時の爆風による機能損失 高熱による機能損失 上記機能損失があると003/004を満足できないため | L12: ● | M12: ● | N12: ● | O12: ● | P12: ● | R12: ● | S12: ● | T12: ● | U12: ● | V12: ● | W12: ● | AJ12: ● | AK12: ● | AN12: ● | AO12: ● | AS12: ● | AU12: =IF($B12="","","BATs-"&TEXT(COUNTIF($B$8:$B12,"?*"),"000")) -> BATs-005 | AV12: 熱拡散安全性能 | AW12: 脱落・剥離・破損なく形状を保持する | BA12: これは、絶縁カバーの事？？ Assy評価でアッパーカバーの開き具合見ておこう！ MtoPと差がないと思うけど、、、セルのふくらみで、アンダーケース側面が 変形して、アッパーカバーが下がってくることないか？
A13: =IF($B13="","","BATs-"&TEXT(COUNTIF($B$8:$B13,"?*"),"000")) -> BATs-006 | B13: 熱拡散安全性能 | C13: 衝突変形後も活電部とアッパーカバーの接触を防ぐ | D13: 絶縁抵抗100MΩ以上 衝突による割れ、変形、破損による保護対象範囲のリークパス形成なきこと | E13: FMVSS 305a（衝突後の電気安全） | F13: 完了 | G13: ＜絶縁カバー＞ 未検討 | K13: 総電圧：560 V 漏れ電流：5.6 μA 発熱量：3.14 mW 100MΩであれば発熱量は無視できるレベルと判断 | O13: ● | W13: ● | AU13: =IF($B13="","","BATs-"&TEXT(COUNTIF($B$8:$B13,"?*"),"000")) -> BATs-006 | AV13: 熱拡散安全性能 | AW13: 衝突変形後も活電部とアッパーカバーの接触を防ぐ | BA13: これは、熱拡散とは違う？？ 端セル周辺構造の変化はCAEで見ているので、実機との整合を取ってください。
A14: =IF($B14="","","BATs-"&TEXT(COUNTIF($B$8:$B14,"?*"),"000")) -> BATs-007 | B14: 熱拡散安全性能 | C14: セルと冷却器の接触を維持する | D14: 熱暴走発生後、<対象部品>でセルと熱伝導材との間に剥離を生じてはならない。 | E14: 熱拡散機能主査DR チェックポイント集より | F14: 完了 | G14: 未検討？ <構造用接着・構造用接着剤> CAE：GT-SUITEで温度推定。構造用接着剤及び冷却器接着剤をモデルに入れて計算。 | H14: トリガーセル,隣接セルの腹面乗下面及びLWRケース上面の熱電対添付。CAEの合わせこみに使用する。（セル発熱プロファイルを同定） | I14: CAE：GT-SUITEで温度推定。構造用接着剤及び冷却器接着剤をモデルに入れて計算。セルの発熱プロファイル及び上面雰囲気温度はLi6.B過去プロジェクトより流用 (※セルが変わった場合は一度ミニモジュール試験が必要。また連鎖した場合の発熱プロファイルは異なると思われるため、2セル試験にて同定予定） コリレーション： | U14: ● | X14: ● | Y14: ● | AJ14: ● | AK14: ● | AU14: =IF($B14="","","BATs-"&TEXT(COUNTIF($B$8:$B14,"?*"),"000")) -> BATs-007 | AV14: 熱拡散安全性能 | AW14: セルと冷却器の接触を維持する | BA14: CtoPでは、接着剤でRFに接着しているのみ。熱影響で接着力が下がることが想定される。上面方向に噴出している分には、セルはその場に居続けると思われる。実機では、何を見る？？
A15: =IF($B15="","","BATs-"&TEXT(COUNTIF($B$8:$B15,"?*"),"000")) -> BATs-008 | B15: 熱拡散安全性能 | C15: アッパーケースを断熱する（カチオン自己発火防止） | D15: 熱拡散試験中、アッパーケースとアッパー断熱は温度をカチオン発火点以下でなければならない。 | E15: 熱拡散機能主査DR チェックポイント集より | F15: 完了 | G15: <UPR断熱材> 45PL以上の熱伝導率を確認 | H15: ＜UPR断熱材＞ UPR断熱材裏面温度測定 | I15: 熱伝導率測定 | R15: ● | V15: ● | AU15: =IF($B15="","","BATs-"&TEXT(COUNTIF($B$8:$B15,"?*"),"000")) -> BATs-008 | AV15: 熱拡散安全性能 | AW15: アッパーケースを断熱する | BA15: Assyではカバー開き量を見る。＝セルとカバーの距離の変化。 あとは、セル単品バラツキとアッパー断熱材の耐力を単品で。10末に向けて計画！
A16: =IF($B16="","","BATs-"&TEXT(COUNTIF($B$8:$B16,"?*"),"000")) -> BATs-009 | B16: 熱拡散安全性能 | C16: 高温金属片（ブラスト状発熱）に対するブラスト対策を講じる | D16: 熱拡散試験後、<対象部品>はブラストによる破損が生じてはならない。 熱拡散試験後、<対象部品>は絶縁抵抗を100MΩ以上に維持しなければならない | E16: 熱拡散機能主査DR チェックポイント集より | F16: 完了 | G16: 未検討？ ＜絶縁カバー、PN絶縁板＞ TaG試験にて1サイクル=マイカ同等の性能は確保済み、今後実試験とTaG試験のダメージコリレをとって行く予定。 <アッパー断熱材> T&G試験(※課題あり)にて45PL以上のサイクル数を確認 <シール> 未検討、高温金属片の飛散範囲が予測できない | H16: ＜シール＞ CTPパックまたは形状を造りこんだミニモ試験で、端セル熱暴走させれば、試験後の飛散範囲を確認できる | I16: ガス流れはCAEで確認していく。 見積り手法未検討 シール部の見積もりが出来ていない。 発生確率が不明。 | O16: ● | P16: ● | R16: ● | S16: ● | T16: ● | V16: ● | W16: ● | X16: ● | AS16: ● | AU16: =IF($B16="","","BATs-"&TEXT(COUNTIF($B$8:$B16,"?*"),"000")) -> BATs-009 | AV16: 熱拡散安全性能 | AW16: 高温金属片（ブラスト状発熱）に対するブラスト対策を講じる | BA16: 同上でよい？？
A17: =IF($B17="","","BATs-"&TEXT(COUNTIF($B$8:$B17,"?*"),"000")) -> BATs-010 | B17: 熱拡散安全性能 | C17: パック内への酸素流入によるガス発火を防止する（可逆性排煙バルブの設定） | D17: 熱拡散試験後、<対象部品>ではシールの破損が生じてはならない。 熱拡散試験中、排煙バルブは外部からパック内への酸素逆流を防止しなければならない （解：可逆性排煙バルブ） | E17: 熱拡散機能主査DR チェックポイント集より | F17: 完了 | G17: 未検討？ 45PLの内圧と余剰空間の差から、内圧見積もりと圧力解放弁の開弁圧を比較。 | P17: ● | S17: ● | T17: ● | U17: ● | V17: ● | AI17: ● | AU17: =IF($B17="","","BATs-"&TEXT(COUNTIF($B$8:$B17,"?*"),"000")) -> BATs-010 | AV17: 熱拡散安全性能 | AW17: パック内への酸素流入によるガス発火を防止する（可逆性排煙バルブの設定） | BA17: ”過圧を逃がす”の部分で見ればよい？
A18: =IF($B18="","","BATs-"&TEXT(COUNTIF($B$8:$B18,"?*"),"000")) -> BATs-011 | B18: 熱拡散安全性能 | C18: 呼吸膜からの酸素流入を制御する | D18: 不要と判断 | E18: 熱拡散機能主査DR チェックポイント集より | F18: 完了 | G18: 机上：図面DR 圧力解放弁と呼吸膜の搭載位置について、45PLと比較。 | I18: 机上：図面DR 圧力解放弁と呼吸膜の搭載位置について、45PLと比較。 | S18: ● | T18: ● | X18: ● | AU18: =IF($B18="","","BATs-"&TEXT(COUNTIF($B$8:$B18,"?*"),"000")) -> BATs-011 | AV18: 熱拡散安全性能 | AW18: 呼吸膜からの酸素流入を制御する | BA18: 同上でよい？？
A19: =IF($B19="","","BATs-"&TEXT(COUNTIF($B$8:$B19,"?*"),"000")) -> BATs-012 | B19: 熱拡散安全性能 | C19: 排煙弁と呼吸膜を同一方向に配置し、セルを跨がない搭載とする | D19: 排煙弁と呼吸膜を同一方向に配置する | E19: 熱拡散機能主査DR チェックポイント集より | F19: 完了 | G19: 机上：図面DRによる要件を満たすことを確認 | I19: 机上：図面DRによる要件を満たすことを確認 | S19: ● | T19: ● | AU19: =IF($B19="","","BATs-"&TEXT(COUNTIF($B$8:$B19,"?*"),"000")) -> BATs-012 | AV19: 熱拡散安全性能 | AW19: 排煙弁と呼吸膜を同一方向に配置し、セルを跨がない搭載とする | BA19: 同上でよい？？
A20: =IF($B20="","","BATs-"&TEXT(COUNTIF($B$8:$B20,"?*"),"000")) -> BATs-013 | B20: 熱拡散安全性能 | C20: セル安全弁をラプチャ（破裂的開口）させず、安定した発煙状態を維持する | D20: 熱拡散試験中、セルは安全弁以外に開口を生じてはならない。 熱拡散試験中、セルからの排煙は安全弁からのみ行わなければならない。 | E20: 熱拡散機能主査DR チェックポイント集より | F20: 完了 | I20: 単品要素試験： Li6.Bの結果より、ラプチャ無しを確認 | X20: ● | AU20: =IF($B20="","","BATs-"&TEXT(COUNTIF($B$8:$B20,"?*"),"000")) -> BATs-013 | AV20: 熱拡散安全性能 | AW20: セル安全弁をラプチャ（破裂的開口）させず、安定した発煙状態を維持する | BA20: これは、、、セル屋さんに言いたいけど。。 サイドラプチャや底面側から開裂して熱伝導材を剥がす現象も実際にある！ どういう条件だとそれが起きるか？？？今回の評価と切り分けて、考える！ あと、今回のCtoP底側面を構造用接着剤で固めるので初期の開裂は防げることを期待！
A21: =IF($B21="","","BATs-"&TEXT(COUNTIF($B$8:$B21,"?*"),"000")) -> BATs-014 | B21: 熱拡散安全性能 | C21: セル内電極温度上昇を抑制して熱暴走させないこと | D21: 熱拡散試験中、<対象部品>では隣接セル内電極温度を150℃以下に維持しなければならない。 | E21: BVP素性効率向上検討会 次世代BEV/PHEV電池パック開発 期初計画 ’26/6/3 スライドP30より | F21: 完了 | I21: CAE：GT-SUITEで温度推定。 | K21: 隣接セルが熱暴走に至る温度を設定する | L21: ● | X21: ● | AJ21: ● | AK21: ● | AU21: =IF($B21="","","BATs-"&TEXT(COUNTIF($B$8:$B21,"?*"),"000")) -> BATs-014 | AV21: 熱拡散安全性能 | AW21: セル内電極温度上昇を抑制して熱暴走させないこと | AX21: 解析モデル上の発熱開始条件（製品全体の一般的な温度目標値ではない）／出典スライド30 | AY21: 250321_プロ検_年度まとめ.pptx / 260317_内山田相談役報告_次世代電池パック開発（普及版）.pptx / 260528_素性効率向上検討会_BVPx次世代コンセプト_期初計画.pptx | BA21: セル間断熱材、下面冷却はMtoP同等。RF直付けによる熱移動が変化点となるが、良くなる方向と想像。計算してみて！
A22: =IF($B22="","","BATs-"&TEXT(COUNTIF($B$8:$B22,"?*"),"000")) -> BATs-015 | B22: 熱拡散安全性能 | C22: 1セルのみ開弁し、隣接セルが開弁しないこと。 | D22: 熱拡散試験中、<対象部品>は隣接セルの腹両面の左右温度の平均温度が150℃以下に維持しなければならない。 （測定開始温度、部品ばらつきを考慮すること） | E22: 熱拡散機能主査DR チェックポイント集より | F22: 完了 | G22: <セル間断熱材> CAE：GT-SUITEで温度推定。 断熱材4.55mmで45PL同等○○○℃見積もり。150℃以下を確認。 | I22: CAE：GT-SUITEで温度推定。 | K22: 隣接セルが熱暴走に至る温度を設定する | L22: ● | M22: ● | N22: ● | U22: ● | X22: ● | AJ22: ● | AK22: ● | AN22: ● | AO22: ● | AU22: =IF($B22="","","BATs-"&TEXT(COUNTIF($B$8:$B22,"?*"),"000")) -> BATs-015 | AV22: 熱拡散安全性能 | AW22: 1セルのみ開弁し、隣接セルが開弁しないこと。 | AX22: 出典スライド31（解析結果 水準2-③） | AY22: 260528_素性効率向上検討会_BVPx次世代コンセプト_期初計画.pdf 熱拡散機能主査DR_チェックポイント(見本).pptx | BA22: 隣接150度以下狙いのハズ！
A23: =IF($B23="","","BATs-"&TEXT(COUNTIF($B$8:$B23,"?*"),"000")) -> BATs-016 | B23: 熱拡散安全性能 | C23: 電池パックからの排煙が車両影響ない位置に設定すること | D23: 熱暴走発生時、排煙ガスはボディシール耐熱温度以下であること | E23: 車両シール部への客室内への影響を考慮 | F23: 完了 | G23: 車両企画未決のため、今回対象外？ | I23: 車両企画未決のため、対象外。 | S23: ● | V23: ● | AU23: =IF($B23="","","BATs-"&TEXT(COUNTIF($B$8:$B23,"?*"),"000")) -> BATs-016 | AV23: 熱拡散安全性能 | AW23: 電池パックからの排煙が車両影響ない位置に設定すること | BA23: 別議論。
A24: =IF($B24="","","BATs-"&TEXT(COUNTIF($B$8:$B24,"?*"),"000")) -> BATs-017 | B24: 熱拡散安全性能 | C24: パックシール部温度・圧力を抑制し、シールが溶損しないこと | D24: 熱暴走発生時、<対象部品>はシール部温度を溶損温度未満に維持しなければならない。 熱暴走発生時、<対象部品>はシール部圧力を溶損・破損圧力未満に維持しなければならない。 | E24: シール破損によるパック外への発煙、発火を防止するため | F24: 完了 | G24: 未検討？ | I24: 机上 45PLからの変化点より見積もり | P24: ● | R24: ● | S24: ● | U24: ● | V24: ● | X24: ● | AI24: ● | AU24: =IF($B24="","","BATs-"&TEXT(COUNTIF($B$8:$B24,"?*"),"000")) -> BATs-017 | AV24: 熱拡散安全性能 | AW24: パックシール部温度・圧力を抑制し、シールが溶損しないこと | AY24: 260528_素性効率向上検討会_BVPx次世代コンセプト_期初計画.pptx | BA24: ”合わせ面からの漏煙・・・”の部分で見ればよい？
A25: =IF($B25="","","BATs-"&TEXT(COUNTIF($B$8:$B25,"?*"),"000")) -> BATs-018 | B25: 熱拡散安全性能 | C25: トリガーガス温度を抑制すること | E25: BATs-038に統合 熱拡散機能主査DR チェックポイント集より | F25: 完了 | X25: ● | AU25: =IF($B25="","","BATs-"&TEXT(COUNTIF($B$8:$B25,"?*"),"000")) -> BATs-018 | AV25: 熱拡散安全性能 | AW25: トリガーガス温度を抑制すること | AY25: 熱拡散機能主査DR_チェックポイント(熱拡散機能主査DR_チェックポイント(見本).pptx見本).pptx | BA25: これって、ヒーター議論の事？別枠で。。。
A26: =IF($B26="","","BATs-"&TEXT(COUNTIF($B$8:$B26,"?*"),"000")) -> BATs-019 | B26: 熱拡散安全性能 | C26: 排煙口と点火源が十分に離れた配置とすること（排煙口と点火源の距離、方向、存在位置） | D26: <対象部品>は排煙口と点火源との最短距離を45PL以上確保しなければならない。 Any positionでブラスト角度±35度内に排煙バルブを設定しないこと。 | E26: 排煙ガス着火（引火） ＞ 排煙ガスと点火源が接触 ＞ 排煙ガスが点火源に近づく ＞ 排煙口と点火源が近い | F26: 完了 | G26: 未検討？ 圧力解放弁の位置はセルから45PL同等以上離れている？ | S26: ● | T26: ● | X26: ● | Z26: ● | AA26: ● | AB26: ● | AD26: ● | AE26: ● | AG26: ● | AN26: ● | AU26: =IF($B26="","","BATs-"&TEXT(COUNTIF($B$8:$B26,"?*"),"000")) -> BATs-019 | AV26: 熱拡散安全性能 | AW26: 排煙口と点火源が十分に離れた配置とすること（排煙口と点火源の距離を確保する） | AY26: 電池パック発火FTA V2 | BA26: ？？ エニーポジションで発煙する前提だと排煙口設置位置は限定される。MtoPと比べて不利になるようなら、考える。
A27: =IF($B27="","","BATs-"&TEXT(COUNTIF($B$8:$B27,"?*"),"000")) -> BATs-020 | B27: 熱拡散安全性能 | C27: 排煙流速を過大にしない排煙経路設計とすること（点火源への到達を抑制する流速に制御する） | E27: BATs-019に統合 排煙ガス着火（引火） ＞ 排煙ガスと点火源が接触 ＞ 排煙ガスが点火源に近づく ＞ 排煙流速が早い | F27: 完了 | S27: ● | T27: ● | AU27: =IF($B27="","","BATs-"&TEXT(COUNTIF($B$8:$B27,"?*"),"000")) -> BATs-020 | AV27: 熱拡散安全性能 | AW27: 排煙流速を過大にしない排煙経路設計とすること（点火源への到達を抑制する流速に制御する） | AY27: 電池パック発火FTA V2 | BA27: MtoPと差がないことの確認
A28: =IF($B28="","","BATs-"&TEXT(COUNTIF($B$8:$B28,"?*"),"000")) -> BATs-021 | B28: 熱拡散安全性能 | C28: 点火源となり得る範囲を最小化する構造とすること（点火源の存在範囲を限定する） | E28: BATs-019に統合 排煙ガス着火（引火） ＞ 排煙ガスと点火源が接触 ＞ 排煙ガスが点火源に近づく ＞ 点火源の範囲が広い | F28: 完了 | W28: ● | X28: ● | Z28: ● | AA28: ● | AB28: ● | AD28: ● | AE28: ● | AF28: ● | AG28: ● | AN28: ● | AU28: =IF($B28="","","BATs-"&TEXT(COUNTIF($B$8:$B28,"?*"),"000")) -> BATs-021 | AV28: 熱拡散安全性能 | AW28: 点火源となり得る範囲を最小化する構造とすること（点火源の存在範囲を限定する） | AY28: 電池パック発火FTA V2 | BA28: 同上でよい？？
A29: =IF($B29="","","BATs-"&TEXT(COUNTIF($B$8:$B29,"?*"),"000")) -> BATs-022 | B29: 熱拡散安全性能 | C29: 排煙方向に点火源が存在しないレイアウトとすること（排煙方向と点火源配置を分離する） | E29: BATs-019に統合 排煙ガス着火（引火） ＞ 排煙ガスと点火源が接触 ＞ 排煙ガスが点火源に近づく ＞ 排煙方向に点火源が存在 | F29: 完了 | S29: ● | W29: ● | X29: ● | Z29: ● | AA29: ● | AB29: ● | AD29: ● | AE29: ● | AF29: ● | AG29: ● | AU29: =IF($B29="","","BATs-"&TEXT(COUNTIF($B$8:$B29,"?*"),"000")) -> BATs-022 | AV29: 熱拡散安全性能 | AW29: 排煙方向に点火源が存在しないレイアウトとすること（排煙方向と点火源配置を分離する） | AY29: 電池パック発火FTA V2 | BA29: 同上でよい？？
A30: =IF($B30="","","BATs-"&TEXT(COUNTIF($B$8:$B30,"?*"),"000")) -> BATs-023 | B30: 熱拡散安全性能 | C30: UPR×LWR・コネクタブロックのシール強度を十分に確保すること（シール破綻を防止する強度を持たせる） | D30: 熱暴走発生時、<対象部品>のシールストレングスは発煙時の加圧により発生するシール線荷重を上回らなければならない | E30: 排煙ガス着火（引火） ＞ 排煙ガスと点火源が接触 ＞ 排煙ガス近くで点火源が発生（パック内） ＞ パック内に酸素が流入 ＞ シール材破綻（UPR×LWR、コネクタブロック） ＞ シール強度不足 | F30: 完了 | G30: BATs-001と同じ | P30: ● | S30: ● | U30: ● | V30: ● | X30: ● | AI30: ● | AU30: =IF($B30="","","BATs-"&TEXT(COUNTIF($B$8:$B30,"?*"),"000")) -> BATs-023 | AV30: 熱拡散安全性能 | AW30: UPR×LWR・コネクタブロックのシール強度を十分に確保すること（シール破綻を防止する強度を持たせる） | AY30: 電池パック発火FTA V2 | BA30: MtoPと差がないことの確認
A31: =IF($B31="","","BATs-"&TEXT(COUNTIF($B$8:$B31,"?*"),"000")) -> BATs-024 | B31: 熱拡散安全性能 | C31: セルブラストの発生・波及を抑制する構造とすること（セルブラストによる点火源発生を抑える） | D31: 熱暴走発生時、セルから発生するガス圧力、噴出範囲は[Li6.B]同等以下でなければならない。 （セル単品排煙試験データ） | E31: 排煙ガス着火（引火） ＞ 排煙ガスと点火源が接触 ＞ 排煙ガス近くで点火源が発生（パック内） ＞ セルブラスト | F31: 完了 | O31: ● | R31: ● | V31: ● | AU31: =IF($B31="","","BATs-"&TEXT(COUNTIF($B$8:$B31,"?*"),"000")) -> BATs-024 | AV31: 熱拡散安全性能 | AW31: セルブラストの発生・波及を抑制する構造とすること（セルブラストによる点火源発生を抑える） | AY31: 電池パック発火FTA V2 | BA31: セルブラストの発生を抑制するって何？？？ 波及を抑制するは、絶縁カバー設計でいいのかな？
A32: =IF($B32="","","BATs-"&TEXT(COUNTIF($B$8:$B32,"?*"),"000")) -> BATs-025 | B32: 熱拡散安全性能 | C32: シール部が想定内圧上昇に耐える耐圧性能を有すること（内圧上昇によるシール破綻を防ぐ） | E32: 排煙ガス着火（引火） ＞ 排煙ガスと点火源が接触 ＞ 排煙ガス近くで点火源が発生（パック内） ＞ パック内に酸素が流入 ＞ シール材破綻（UPR×LWR、コネクタブロック） ＞ 内圧上昇 | F32: 完了 | G32: ＜シール＞ シール単体評価でストレングス測定 | H32: ＜シール＞ パック内圧測定 | P32: ● | S32: ● | T32: ● | AI32: ● | AU32: =IF($B32="","","BATs-"&TEXT(COUNTIF($B$8:$B32,"?*"),"000")) -> BATs-025 | AV32: 熱拡散安全性能 | AW32: シール部が想定内圧上昇に耐える耐圧性能を有すること（内圧上昇によるシール破綻を防ぐ） | AY32: 電池パック発火FTA V2 | BA32: ”合わせ面からの漏煙・・・”の部分で見ればよい？
A33: =IF($B33="","","BATs-"&TEXT(COUNTIF($B$8:$B33,"?*"),"000")) -> BATs-026 | B33: 熱拡散安全性能 | C33: シール材が想定温度に耐える耐熱性能を有すること（溶損によるシール破綻を防ぐ） | D33: シール耐熱温度は、熱暴走中にシールに接するガス温度以上であること | E33: 排煙ガス着火（引火） ＞ 排煙ガスと点火源が接触 ＞ 排煙ガス近くで点火源が発生（パック内） ＞ パック内に酸素が流入 ＞ シール材破綻（UPR×LWR、コネクタブロック） ＞ シール耐熱不足(溶損) | F33: 完了 | G33: ＜シール＞ シール単体評価でストレングス測定 | H33: ＜シール＞ シール部温度測定 | P33: ● | S33: ● | T33: ● | AI33: ● | AU33: =IF($B33="","","BATs-"&TEXT(COUNTIF($B$8:$B33,"?*"),"000")) -> BATs-026 | AV33: 熱拡散安全性能 | AW33: シール材が想定温度に耐える耐熱性能を有すること（溶損によるシール破綻を防ぐ） | AY33: 電池パック発火FTA V2 | BA33: 同上でよい？？
A34: =IF($B34="","","BATs-"&TEXT(COUNTIF($B$8:$B34,"?*"),"000")) -> BATs-027 | B34: 熱拡散安全性能 | C34: シール部近傍の温度上昇を抑制すること（シール耐熱を超える温度上昇を防ぐ） | D34: BATs-026NGであれば要件として定義するため、一旦なし | E34: 排煙ガス着火（引火） ＞ 排煙ガスと点火源が接触 ＞ 排煙ガス近くで点火源が発生（パック内） ＞ パック内に酸素が流入 ＞ シール材破綻（UPR×LWR、コネクタブロック） ＞ 温度上昇 | F34: 完了 | G34: ＜シール＞ シール単体評価でストレングス測定 | H34: ＜シール＞ シール部温度測定 | P34: ● | S34: ● | T34: ● | U34: ● | V34: ● | AI34: ● | AU34: =IF($B34="","","BATs-"&TEXT(COUNTIF($B$8:$B34,"?*"),"000")) -> BATs-027 | AV34: 熱拡散安全性能 | AW34: シール部近傍の温度上昇を抑制すること（シール耐熱を超える温度上昇を防ぐ） | AY34: 電池パック発火FTA V2 | BA34: 同上でよい？？
A35: =IF($B35="","","BATs-"&TEXT(COUNTIF($B$8:$B35,"?*"),"000")) -> BATs-028 | B35: 熱拡散安全性能 | C35: ケース近傍の温度上昇を抑制すること（ケース穴開きに至る温度上昇を防ぐ） | D35: 噴出物蓄積による短絡経路形成で短絡しない構造とすること | E35: 排煙ガス着火（引火） ＞ 排煙ガスと点火源が接触 ＞ 排煙ガス近くで点火源が発生（パック内） ＞ 短絡発生 ＞ ケース穴開き ＞ 温度上昇 | F35: 完了 | R35: ● | U35: ● | V35: ● | AU35: =IF($B35="","","BATs-"&TEXT(COUNTIF($B$8:$B35,"?*"),"000")) -> BATs-028 | AV35: 熱拡散安全性能 | AW35: ケース近傍の温度上昇を抑制すること（ケース穴開きに至る温度上昇を防ぐ） | AY35: 電池パック発火FTA V2 | BA35: CtoP構造の変化あり。端セルで発煙した場合は、ケース温度変わるだろうね。。。 CtoP構造での端セル発煙時の温度を推定、MtoPと比較、シール絶対強度（データあり）と比較！
A36: =IF($B36="","","BATs-"&TEXT(COUNTIF($B$8:$B36,"?*"),"000")) -> BATs-029 | B36: 熱拡散安全性能 | C36: 短絡発生を防止する絶縁・保護構造を有すること（短絡によるケース穴開きを防ぐ） | D36: 熱拡散試験後、<対象部品>は絶縁抵抗を100MΩ以上に維持しなければならない 熱暴走発生時、<対象部品>はセル間、MODバスバ、BBMコネクタ、セルの直上において短絡を生じさせてはならない。 | E36: 排煙ガス着火（引火） ＞ 排煙ガスと点火源が接触 ＞ 排煙ガス近くで点火源が発生（パック内） ＞ 短絡発生 ＞ ケース穴開き ＞ 短絡 | F36: 完了 | G36: ＜絶縁カバー＞ 活電部カバー済み、ただし、MOD間バスバと絶縁カバーのラップ量がﾂﾗｲﾁ設定のため評価にて確認したい | H36: ＜絶縁カバー＞ 噴出物の挙動、圧力による変形で活電部が露出しないか | K36: 総電圧：560 V 漏れ電流：5.6 μA 発熱量：3.14 mW 100MΩであれば発熱量は無視できるレベルと判断 | O36: ● | R36: ● | W36: ● | Z36: ● | AA36: ● | AB36: ● | AD36: ● | AE36: ● | AF36: ● | AG36: ● | AN36: ● | AR36: ● | AS36: ● | AU36: =IF($B36="","","BATs-"&TEXT(COUNTIF($B$8:$B36,"?*"),"000")) -> BATs-029 | AV36: 熱拡散安全性能 | AW36: 短絡発生を防止する絶縁・保護構造を有すること（短絡によるケース穴開きを防ぐ） | AY36: 電池パック発火FTA V2 | BA36: ”アッパーケース断熱・・・”の部分で見ればよい？
A37: =IF($B37="","","BATs-"&TEXT(COUNTIF($B$8:$B37,"?*"),"000")) -> BATs-030 | B37: 熱拡散安全性能 | C37: ケースが想定温度に耐える耐熱性能を有すること（耐熱不足によるケース穴開きを防ぐ） | D37: 熱暴走発生時、アッパーケースは噴出ガス、噴出物の温度により穴あき、発火なきこと | E37: 排煙ガス着火（引火） ＞ 排煙ガスと点火源が接触 ＞ 排煙ガス近くで点火源が発生（パック内） ＞ 短絡発生 ＞ ケース穴開き ＞ ケース耐熱不足 | F37: 完了 | R37: ● | U37: ● | V37: ● | X37: ● | AH37: ● | AU37: =IF($B37="","","BATs-"&TEXT(COUNTIF($B$8:$B37,"?*"),"000")) -> BATs-030 | AV37: 熱拡散安全性能 | AW37: ケースが想定温度に耐える耐熱性能を有すること（耐熱不足によるケース穴開きを防ぐ） | AY37: 電池パック発火FTA V2 | BA37: ”アッパーケース断熱・・・”の部分で見ればよい？
A38: =IF($B38="","","BATs-"&TEXT(COUNTIF($B$8:$B38,"?*"),"000")) -> BATs-031 | B38: 熱拡散安全性能 | C38: ケース内圧の上昇を抑制すること（内圧上昇によるケース穴開きを防ぐ） | D38: 熱暴走発生時、排煙バルブはシール部耐圧力、アッパーケース、ロアケース 耐圧力以下でバルブ解放させること | E38: 排煙ガス着火（引火） ＞ 排煙ガスと点火源が接触 ＞ 排煙ガス近くで点火源が発生（パック内） ＞ 短絡発生 ＞ ケース穴開き ＞ 内圧上昇 | F38: 完了 | S38: ● | T38: ● | AU38: =IF($B38="","","BATs-"&TEXT(COUNTIF($B$8:$B38,"?*"),"000")) -> BATs-031 | AV38: 熱拡散安全性能 | AW38: ケース内圧の上昇を抑制すること（内圧上昇によるケース穴開きを防ぐ） | AY38: 電池パック発火FTA V2 | BA38: ”合わせ面からの漏煙・・・”の部分で見ればよい？
A39: =IF($B39="","","BATs-"&TEXT(COUNTIF($B$8:$B39,"?*"),"000")) -> BATs-032 | B39: 熱拡散安全性能 | C39: ケースが想定荷重・内圧に耐える強度を有すること（強度不足によるケース穴開きを防ぐ） | D39: 熱暴走発生時、アッパーケース・ロアケースはセルガス圧力により破損、穴あき無き事 | E39: 排煙ガス着火（引火） ＞ 排煙ガスと点火源が接触 ＞ 排煙ガス近くで点火源が発生（パック内） ＞ 短絡発生 ＞ ケース穴開き ＞ ケース強度不足 | F39: 完了 | M39: ● | N39: ● | P39: ● | U39: ● | V39: ● | AI39: ● | AU39: =IF($B39="","","BATs-"&TEXT(COUNTIF($B$8:$B39,"?*"),"000")) -> BATs-032 | AV39: 熱拡散安全性能 | AW39: ケースが想定荷重・内圧に耐える強度を有すること（強度不足によるケース穴開きを防ぐ） | AY39: 電池パック発火FTA V2 | BA39: 流石にこれはないでしょう。。。
A40: =IF($B40="","","BATs-"&TEXT(COUNTIF($B$8:$B40,"?*"),"000")) -> BATs-033 | B40: 熱拡散安全性能 | C40: 排煙バルブが想定内圧に耐える耐圧性能を有すること（耐圧不足によるバルブ破損を防ぐ） | D40: 熱暴走発生時、排煙バルブは規定圧力以上で開放することができること | E40: 排煙ガス着火（引火） ＞ 排煙ガスと点火源が接触 ＞ 排煙ガス近くで点火源が発生（パック内） ＞ 短絡発生 ＞ 排煙バルブ破損 ＞ バルブ耐圧不足 | F40: 完了 | S40: ● | AU40: =IF($B40="","","BATs-"&TEXT(COUNTIF($B$8:$B40,"?*"),"000")) -> BATs-033 | AV40: 熱拡散安全性能 | AW40: 排煙バルブが想定内圧に耐える耐圧性能を有すること（耐圧不足によるバルブ破損を防ぐ） | AY40: 電池パック発火FTA V2 | BA40: MtoPと差がない
A41: =IF($B41="","","BATs-"&TEXT(COUNTIF($B$8:$B41,"?*"),"000")) -> BATs-034 | B41: 熱拡散安全性能 | C41: 排煙バルブ部の内圧上昇を抑制すること（内圧上昇によるバルブ破損を防ぐ） | D41: 熱暴走発生時、排煙バルブは規定圧力以上で開放することができること | E41: 排煙ガス着火（引火） ＞ 排煙ガスと点火源が接触 ＞ 排煙ガス近くで点火源が発生（パック内） ＞ 短絡発生 ＞ 排煙バルブ破損 ＞ 内圧上昇 | F41: 完了 | S41: ● | X41: ● | AU41: =IF($B41="","","BATs-"&TEXT(COUNTIF($B$8:$B41,"?*"),"000")) -> BATs-034 | AV41: 熱拡散安全性能 | AW41: 排煙バルブ部の内圧上昇を抑制すること（内圧上昇によるバルブ破損を防ぐ） | AY41: 電池パック発火FTA V2 | BA41: 同上でよい？？
...

Sheet 部品要求マトリクス（熱拡散サブシステム）
A1: 部品別 要求割付マトリクス
A2: 熱拡散防止サブシステムの全要求IDと部品割付を一覧表示
A4: 更新方法：熱拡散防止サブシステム要求のA列へ新しい要求IDを追加し、同じ行のH～L列へ部品名を入力すると、要求IDは右端、部品名は下行へ自動追加され、該当箇所に「●」が表示されます。
A5: 部品別要求マトリクス
A6: {=_xlfn.LET(_xlpm.idRange,熱拡散防止サブシステム要求!$A$8:$A$1005,_xlpm.hdr,熱拡散防止サブシステム要求!$L$7:$AT$7,_xlpm.alloc,熱拡散防止サブシステム要求!$L$8:$AT$1005,_xlpm.keep,_xlpm.idRange<>"",_xlpm.ids,_xlfn._xlws.FILTER(_xlpm.idRange,_xlpm.keep),_xlpm.data,_xlfn._xlws.FILTER(_xlpm.alloc,_xlpm.keep),_xlpm.parts,_xlfn._xlws.SORT(_xlfn.UNIQUE(_xlfn.TOCOL(_xlpm.hdr,1))),_xlfn.VSTACK(_xlfn.HSTACK("部品名＼要求ID",TRANSPOSE(_xlpm.ids)),_xlfn.HSTACK(_xlpm.parts,_xlfn.MAKEARRAY(ROWS(_xlpm.parts),ROWS(_xlpm.ids),_xlfn.LAMBDA(_xlpm.r,_xlpm.c,IF(SUMPRODUCT(--(_xlpm.hdr=INDEX(_xlpm.parts,_xlpm.r)),--(INDEX(_xlpm.data,_xlpm.c,0)="●"))>0,"●",""))))))} -> 部品名＼要求ID | B6: BATs-001 | C6: BATs-002 | D6: BATs-003 | E6: BATs-004 | F6: BATs-005 | G6: BATs-006 | H6: BATs-007 | I6: BATs-008 | J6: BATs-009 | K6: BATs-010 | L6: BATs-011 | M6: BATs-012 | N6: BATs-013 | O6: BATs-014 | P6: BATs-015 | Q6: BATs-016 | R6: BATs-017 | S6: BATs-018 | T6: BATs-019 | U6: BATs-020 | V6: BATs-021 | W6: BATs-022 | X6: BATs-023 | Y6: BATs-024 | Z6: BATs-025 | AA6: BATs-026 | AB6: BATs-027 | AC6: BATs-028 | AD6: BATs-029 | AE6: BATs-030 | AF6: BATs-031 | AG6: BATs-032 | AH6: BATs-033 | AI6: BATs-034 | AJ6: BATs-035 | AK6: BATs-036 | AL6: BATs-037 | AM6: BATs-038 | AN6: BATs-039 | AO6: BATs-040 | AP6: BATs-041 | AQ6: BATs-042 | AR6: BATs-043 | AS6: BATs-044 | AT6: BATs-045 | AU6: BATs-046 | AV6: BATs-047 | AW6: BATs-048 | AX6: BATs-049 | AY6: BATs-050 | AZ6: BATs-051 | BA6: BATs-052 | BB6: BATs-053 | BC6: BATs-054 | BD6: BATs-055 | BE6: BATs-056 | BF6: BATs-057 | BG6: BATs-058 | BH6: BATs-059 | BI6: BATs-060 | BJ6: BATs-061 | BK6: BATs-062 | BL6: BATs-063 | BM6: BATs-064 | BN6: BATs-065 | BO6: BATs-066
A7: BBM | V7: ● | W7: ● | AD7: ● | AO7: ● | AP7: ● | AU7: ● | AW7: ● | AX7: ● | AZ7: ● | BB7: ● | BI7: ●
A8: BBMコネクタ | D8: ● | E8: ● | T8: ● | V8: ● | W8: ● | AD8: ● | AO8: ● | AP8: ● | BB8: ● | BI8: ●
A9: ECU | T9: ● | V9: ● | W9: ● | AD9: ● | AO9: ● | AP9: ● | AW9: ● | AX9: ● | AZ9: ● | BB9: ● | BI9: ● | BM9: ● | BN9: ●
A10: J/B | D10: ● | E10: ● | T10: ● | V10: ● | W10: ● | AD10: ● | AO10: ● | AP10: ● | AX10: ● | BB10: ● | BI10: ●
A11: MOD間バスバ | D11: ● | E11: ● | F11: ● | G11: ● | J11: ● | V11: ● | W11: ● | AD11: ● | AO11: ● | AP11: ● | AS11: ● | BI11: ●
A12: PNコネクタ | B12: ● | T12: ● | V12: ● | W12: ● | AD12: ● | AO12: ● | AP12: ● | AX12: ● | BB12: ● | BI12: ●
A13: PN絶縁板 | D13: ● | E13: ● | F13: ● | J13: ● | AD13: ● | AO13: ● | AP13: ● | BB13: ●
A14: SBM | D14: ● | E14: ● | T14: ● | V14: ● | W14: ● | AD14: ● | AO14: ● | AP14: ● | AW14: ● | AX14: ● | AZ14: ● | BB14: ● | BI14: ●
A15: W/H | D15: ● | E15: ● | AP15: ● | BB15: ●
A16: アッパーケース | B16: ● | C16: ● | D16: ● | E16: ● | F16: ● | I16: ● | J16: ● | K16: ● | Q16: ● | R16: ● | X16: ● | Y16: ● | AB16: ● | AC16: ● | AE16: ● | AG16: ● | AJ16: ● | AO16: ● | AP16: ● | AS16: ● | AT16: ● | AW16: ● | AX16: ● | AZ16: ● | BB16: ● | BC16: ● | BD16: ● | BF16: ● | BH16: ● | BI16: ● | BL16: ●
A17: アッパー断熱 | D17: ● | E17: ● | F17: ● | I17: ● | J17: ● | R17: ● | Y17: ● | AC17: ● | AD17: ● | AE17: ● | AO17: ● | AP17: ● | AS17: ● | AU17: ● | AW17: ● | AX17: ● | AZ17: ● | BB17: ● | BD17: ● | BE17: ● | BF17: ● | BI17: ● | BL17: ●
A18: エンドプレート | F18: ● | P18: ● | AG18: ● | AP18: ● | AU18: ● | BB18: ● | BE18: ● | BI18: ●
A19: コネクタブロック | B19: ● | AE19: ● | AP19: ● | BB19: ● | BC19: ● | BI19: ●
A20: コネクタブロックシール材 | B20: ● | K20: ● | R20: ● | X20: ● | Z20: ● | AA20: ● | AB20: ● | AG20: ● | BB20: ● | BC20: ● | BJ20: ● | BO20: ●
A21: スペーサー | AP21: ● | AW21: ● | AZ21: ● | BB21: ●
A22: セル | B22: ● | C22: ● | D22: ● | E22: ● | H22: ● | J22: ● | L22: ● | N22: ● | O22: ● | P22: ● | R22: ● | S22: ● | T22: ● | V22: ● | W22: ● | X22: ● | AE22: ● | AI22: ● | AJ22: ● | AM22: ● | AO22: ● | AP22: ● | AR22: ● | AT22: ● | AW22: ● | AX22: ● | AZ22: ● | BA22: ● | BB22: ● | BG22: ● | BI22: ●
A23: セルフィルム | H23: ● | AW23: ● | AZ23: ●
A24: セル間断熱材 | F24: ● | O24: ● | P24: ● | AN24: ● | AP24: ● | AU24: ● | AV24: ● | BB24: ● | BE24: ● | BI24: ● | BL24: ●
A25: パックシール材 | B25: ● | C25: ● | F25: ● | J25: ● | K25: ● | R25: ● | X25: ● | Z25: ● | AA25: ● | AB25: ● | AG25: ● | BC25: ● | BJ25: ● | BO25: ●
A26: フェライトコア | AP26: ● | BB26: ● | BI26: ●
A27: ロアケース | B27: ● | C27: ● | D27: ● | E27: ● | F27: ● | H27: ● | K27: ● | P27: ● | R27: ● | X27: ● | AB27: ● | AC27: ● | AE27: ● | AG27: ● | AO27: ● | AP27: ● | AS27: ● | AU27: ● | AW27: ● | AX27: ● | AZ27: ● | BB27: ● | BC27: ● | BD27: ● | BE27: ●
A28: 呼吸膜 | B28: ● | C28: ● | F28: ● | J28: ● | K28: ● | L28: ● | M28: ● | T28: ● | U28: ● | Z28: ● | AA28: ● | AB28: ● | AF28: ● | AL28: ● | BB28: ● | BC28: ● | BJ28: ●
A29: 拘束 | F29: ● | P29: ● | AG29: ● | AP29: ● | AU29: ● | AX29: ● | BB29: ● | BE29: ● | BI29: ●
A30: 構造用接着剤(セル接着剤) | F30: ● | P30: ● | AP30: ● | AU30: ● | AW30: ● | AZ30: ● | BB30: ● | BE30: ●
A31: 高圧ヒューズ | D31: ● | E31: ● | T31: ● | V31: ● | W31: ● | AD31: ● | AO31: ● | AP31: ● | AX31: ● | BB31: ● | BI31: ●
A32: 絶縁カバー | D32: ● | E32: ● | F32: ● | G32: ● | J32: ● | Y32: ● | AD32: ● | AO32: ● | AP32: ● | AQ32: ● | AS32: ● | AW32: ● | AZ32: ● | BB32: ● | BE32: ● | BI32: ● | BL32: ●
A33: 総±バスバー | D33: ● | E33: ● | F33: ● | P33: ● | T33: ● | V33: ● | AD33: ● | AO33: ● | AP33: ● | AS33: ● | AU33: ● | AW33: ● | AX33: ● | AZ33: ● | BB33: ● | BI33: ●
A34: 端子台 | D34: ● | E34: ● | AD34: ● | AP34: ● | BB34: ●
A35: 端絶縁板 | AP35: ● | BB35: ●
A36: 低圧/高圧パックI/Fシール材 | B36: ●
A37: 低圧コネクタ
A38: 熱伝導材 | F38: ● | H38: ● | O38: ● | P38: ● | AP38: ● | AU38: ● | AW38: ● | AZ38: ● | BB38: ● | BE38: ●
A39: 排煙サーミスタ | AP39: ● | BB39: ● | BM39: ● | BN39: ●
A40: 排煙バルブ | B40: ● | C40: ● | F40: ● | J40: ● | K40: ● | L40: ● | M40: ● | Q40: ● | R40: ● | T40: ● | U40: ● | W40: ● | X40: ● | Z40: ● | AA40: ● | AB40: ● | AF40: ● | AH40: ● | AI40: ● | AJ40: ● | AK40: ● | AL40: ● | AT40: ● | AX40: ● | AY40: ● | BB40: ● | BC40: ● | BH40: ● | BI40: ● | BJ40: ● | BK40: ● | BL40: ● | BO40: ●
A41: 冷却器 | F41: ● | H41: ● | O41: ● | P41: ● | AU41: ● | AW41: ● | AZ41: ● | BB41: ●

Sheet 相関性マトリクス
A1: From＼To | B1: 実働応力測定（機器部品耐振動） | C1: 突起乗り越し | D1: 悪路模擬耐久 | E1: 高速波状路模擬耐久 | F1: ねじり耐久 | G1: 山地悪路耐久 | H1: 凹凸路耐久 | I1: サーキット模擬耐久
A2: K-4 高電圧安全・絶縁
A3: BS20 絶縁抵抗性能
A4: BS21 絶縁耐力性能
A5: BS22 高圧接触保護構造
A6: BS23 絶縁距離性能
A7: BS18 外部短絡安全性性能
A8: BAT-007 熱衝撃
A9: BS25 冷却温度制御条件
A10: BS27 動作温度限界性能
A11: BS28 環境動作温度・湿度範囲
A12: K-3 強度・衝突安全
A13: BS11 耐久信頼性性能
... A72: BS41 量産性・サービス安全性能

Sheet 相関性リスト
A1: RelationID | B1: From要求ID | C1: To要求ID | D1: 相関性記号 | E1: 関係種別 | F1: 方向性 | G1: 根拠/出典 | H1: 備考
A2: REL-001 | B2: K-4 高電圧安全・絶縁 | C2: BS20 絶縁抵抗性能 | D2: + | E2: 連成 | F2: From→To | G2: 情報元（出典資料）: 20260402_解析力向上_素性・開発効率向上_V02_展開資料5.pdf
A3: REL-002 | B3: K-4 高電圧安全・絶縁 | C3: BS21 絶縁耐力性能 | D3: + | E3: 連成 | F3: From→To | G3: 情報元（出典資料）: 20260402_解析力向上_素性・開発効率向上_V02_展開資料5.pdf / 250321_プロ検_年度まとめ.pptx / 【部長級】将来BEV_電池×システム先行開発連携.pptx
A4: REL-003 | B4: K-4 高電圧安全・絶縁 | C4: BS22 高圧接触保護構造 | D4: + | E4: 連成 | F4: From→To | G4: 情報元（出典資料）: 20260402_解析力向上_素性・開発効率向上_V02_展開資料5.pdf / 250321_プロ検_年度まとめ.pptx / 【部長級】将来BEV_電池×システム先行開発連携.pptx
A5: REL-004 | B5: K-4 高電圧安全・絶縁 | C5: BS23 絶縁距離性能 | D5: + | E5: 連成 | F5: From→To | G5: 情報元（出典資料）: 20260402_解析力向上_素性・開発効率向上_V02_展開資料5.pdf / 250321_プロ検_年度まとめ.pptx / 【部長級】将来BEV_電池×システム先行開発連携.pptx
A6: REL-005 | B6: K-4 高電圧安全・絶縁 | C6: BS18 外部短絡安全性性能 | D6: + | E6: 連成 | F6: From→To | G6: 情報元（出典資料）: 20260402_解析力向上_素性・開発効率向上_V02_展開資料5.pdf / 250321_プロ検_年度まとめ.pptx / 【部長級】将来BEV_電池×システム先行開発連携.pptx
A7: REL-006 | B7: K-4 高電圧安全・絶縁 | C7: BS31 パック防水性能 | D7: + | E7: 連成 | F7: From→To | G7: 情報元（出典資料）: 20260402_解析力向上_素性・開発効率向上_V02_展開資料5.pdf / 250321_プロ検_年度まとめ.pptx / 【部長級】将来BEV_電池×システム先行開発連携.pptx
A8: REL-007 | B8: K-4 高電圧安全・絶縁 | C8: BS32 水入り検知・防護性能 | D8: + | E8: 連成 | F8: From→To | G8: 情報元（出典資料）: 20260402_解析力向上_素性・開発効率向上_V02_展開資料5.pdf / 250321_プロ検_年度まとめ.pptx / 【部長級】将来BEV_電池×システム先行開発連携.pptx
A9: REL-008 | B9: K-4 高電圧安全・絶縁 | C9: BS33 シール・呼吸膜性能 | D9: + | E9: 連成 | F9: From→To | G9: 情報元（出典資料）: 20260402_解析力向上_素性・開発効率向上_V02_展開資料5.pdf / 250321_プロ検_年度まとめ.pptx / 【部長級】将来BEV_電池×システム先行開発連携.pptx
A10: REL-009 | B10: K-3 強度・衝突安全 | C10: BS11 耐久信頼性性能 | D10: + | E10: 連成 | F10: From→To | G10: 情報元（出典資料）: 20260402_解析力向上_素性・開発効率向上_V02_展開資料5.pdf / 260528_素性効率向上検討会_BVPx次世代コンセプト_期初計画.pptx
A11: REL-010 | B11: K-3 強度・衝突安全 | C11: BS12 振動適合 | D11: + | E11: 連成 | F11: From→To | G11: 情報元（出典資料）: 20260402_解析力向上_素性・開発効率向上_V02_展開資料5.pdf / 260528_素性効率向上検討会_BVPx次世代コンセプト_期初計画.pptx
A12: REL-011 | B12: K-3 強度・衝突安全 | C12: BS16 圧壊安全性性能 | D12: + | E12: 連成 | F12: From→To | G12: 情報元（出典資料）: 20260402_解析力向上_素性・開発効率向上_V02_展開資料5.pdf
A13: REL-012 | B13: K-3 強度・衝突安全 | C13: BS14 路面・落下物干渉防護 | D13: + | E13: 連成 | F13: From→To | G13: 情報元（出典資料）: 20260402_解析力向上_素性・開発効率向上_V02_展開資料5.pdf / 260528_素性効率向上検討会_BVPx次世代コンセプト_期初計画.pptx
... A24: REL-023 | B24: K-7 生産性 | C24: BS41 量産性・サービス安全性能 | D24: + | E24: 連成 | F24: From→To | G24: 情報元（出典資料）: 記載なし

Sheet 他システム影響
A1: 電池パック ⇔ 他システム影響
A2: ・要求一覧（システム要求）の各有効行を全件登録。影響先は根拠確認後に入力する前提。
A3: 影響ID | B3: 管理ID | C3: From要求ID | D3: From 要求名/説明 | E3: To 影響先システム | F3: To 影響先システム2 | G3: To 影響先システム3 | H3: 影響先要求名 | I3: 影響種別(+/-/その他) | J3: 影響方向 | K3: 根拠/出典 | L3: 備考
A4: IMP-001 | B4: BAT-001 | C4: =_xlfn.LET(_xlpm.d,_xlfn.XLOOKUP(B4,システム要求!$A$4:$A$113,システム要求!$D$4:$D$113,""),_xlpm.m,_xlfn.XLOOKUP(B4,システム要求!$A$4:$A$113,システム要求!$C$4:$C$113,""),IF(_xlpm.d<>"",IFERROR(_xlfn.TEXTBEFORE(_xlpm.d,"："),IFERROR(_xlfn.TEXTBEFORE(_xlpm.d,":"),_xlpm.d)),TRIM(B4&" "&_xlpm.m))) -> K-4 高電圧安全・絶縁 | D4: K-4 高電圧安全・絶縁
A5: IMP-002 | B5: BAT-002 | C5: =_xlfn.LET(_xlpm.d,_xlfn.XLOOKUP(B5,システム要求!$A$4:$A$113,システム要求!$D$4:$D$113,""),_xlpm.m,_xlfn.XLOOKUP(B5,システム要求!$A$4:$A$113,システム要求!$C$4:$C$113,""),IF(_xlpm.d<>"",IFERROR(_xlfn.TEXTBEFORE(_xlpm.d,"："),IFERROR(_xlfn.TEXTBEFORE(_xlpm.d,":"),_xlpm.d)),TRIM(B5&" "&_xlpm.m))) -> BS20 絶縁抵抗性能 | D5: 高電圧回路とシャーシグラウンド間の絶縁要求
A6: IMP-003 | B6: BAT-003 | C6: =_xlfn.LET(_xlpm.d,_xlfn.XLOOKUP(B6,システム要求!$A$4:$A$113,システム要求!$D$4:$D$113,""),_xlpm.m,_xlfn.XLOOKUP(B6,システム要求!$A$4:$A$113,システム要求!$C$4:$C$113,""),IF(_xlpm.d<>"",IFERROR(_xlfn.TEXTBEFORE(_xlpm.d,"："),IFERROR(_xlfn.TEXTBEFORE(_xlpm.d,":"),_xlpm.d)),TRIM(B6&" "&_xlpm.m))) -> BS21 絶縁耐力性能 | D6: 高電圧印加時の絶縁破壊耐性
A7: IMP-004 | B7: BAT-004 | C7: =_xlfn.LET(_xlpm.d,_xlfn.XLOOKUP(B7,システム要求!$A$4:$A$113,システム要求!$D$4:$D$113,""),_xlpm.m,_xlfn.XLOOKUP(B7,システム要求!$A$4:$A$113,システム要求!$C$4:$C$113,""),IF(_xlpm.d<>"",IFERROR(_xlfn.TEXTBEFORE(_xlpm.d,"："),IFERROR(_xlfn.TEXTBEFORE(_xlpm.d,":"),_xlpm.d)),TRIM(B7&" "&_xlpm.m))) -> BS22 高圧接触保護構造 | D7: 感電防止の物理保護構造（IPXXB等）
A8: IMP-005 | B8: BAT-005 | C8: =_xlfn.LET(_xlpm.d,_xlfn.XLOOKUP(B8,システム要求!$A$4:$A$113,システム要求!$D$4:$D$113,""),_xlpm.m,_xlfn.XLOOKUP(B8,システム要求!$A$4:$A$113,システム要求!$C$4:$C$113,""),IF(_xlpm.d<>"",IFERROR(_xlfn.TEXTBEFORE(_xlpm.d,"："),IFERROR(_xlfn.TEXTBEFORE(_xlpm.d,":"),_xlpm.d)),TRIM(B8&" "&_xlpm.m))) -> BS23 絶縁距離性能 | D8: 沿面距離・空間距離の安全基準
A9: IMP-006 | B9: BAT-006 | C9: =_xlfn.LET(_xlpm.d,_xlfn.XLOOKUP(B9,システム要求!$A$4:$A$113,システム要求!$D$4:$D$113,""),_xlpm.m,_xlfn.XLOOKUP(B9,システム要求!$A$4:$A$113,システム要求!$C$4:$C$113,""),IF(_xlpm.d<>"",IFERROR(_xlfn.TEXTBEFORE(_xlpm.d,"："),IFERROR(_xlfn.TEXTBEFORE(_xlpm.d,":"),_xlpm.d)),TRIM(B9&" "&_xlpm.m))) -> BS18 外部短絡安全性性能 | D9: 外部短絡時の耐性と安全性
A10: IMP-007 | B10: BAT-007 | C10: =_xlfn.LET(_xlpm.d,_xlfn.XLOOKUP(B10,システム要求!$A$4:$A$113,システム要求!$D$4:$D$113,""),_xlpm.m,_xlfn.XLOOKUP(B10,システム要求!$A$4:$A$113,システム要求!$C$4:$C$113,""),IF(_xlpm.d<>"",IFERROR(_xlfn.TEXTBEFORE(_xlpm.d,"："),IFERROR(_xlfn.TEXTBEFORE(_xlpm.d,":"),_xlpm.d)),TRIM(B10&" "&_xlpm.m))) -> 法規(AIS-038 Rev.2)を満足させる | D10: 熱衝撃
A11: IMP-008 | B11: BAT-008 | C11: =_xlfn.LET(_xlpm.d,_xlfn.XLOOKUP(B11,システム要求!$A$4:$A$113,システム要求!$D$4:$D$113,""),_xlpm.m,_xlfn.XLOOKUP(B11,システム要求!$A$4:$A$113,システム要求!$C$4:$C$113,""),IF(_xlpm.d<>"",IFERROR(_xlfn.TEXTBEFORE(_xlpm.d,"："),IFERROR(_xlfn.TEXTBEFORE(_xlpm.d,":"),_xlpm.d)),TRIM(B11&" "&_xlpm.m))) -> 法規(GB38031-2025)を満足させる | D11: セル充放電時の許容温度範囲
A12: IMP-009 | B12: BAT-009 | C12: =_xlfn.LET(_xlpm.d,_xlfn.XLOOKUP(B12,システム要求!$A$4:$A$113,システム要求!$D$4:$D$113,""),_xlpm.m,_xlfn.XLOOKUP(B12,システム要求!$A$4:$A$113,システム要求!$C$4:$C$113,""),IF(_xlpm.d<>"",IFERROR(_xlfn.TEXTBEFORE(_xlpm.d,"："),IFERROR(_xlfn.TEXTBEFORE(_xlpm.d,":"),_xlpm.d)),TRIM(B12&" "&_xlpm.m))) -> 法規(KMVSS 48)を満足させる | D12: 極低温・極高温下のシステム出力動作限界
A13: IMP-010 | B13: BAT-010 | C13: =_xlfn.LET(_xlpm.d,_xlfn.XLOOKUP(B13,システム要求!$A$4:$A$113,システム要求!$D$4:$D$113,""),_xlpm.m,_xlfn.XLOOKUP(B13,システム要求!$A$4:$A$113,システム要求!$C$4:$C$113,""),IF(_xlpm.d<>"",IFERROR(_xlfn.TEXTBEFORE(_xlpm.d,"："),IFERROR(_xlfn.TEXTBEFORE(_xlpm.d,":"),_xlpm.d)),TRIM(B13&" "&_xlpm.m))) -> 法規(FMVSS305a)を満足させる | D13: 車両運用の外的環境仕様
A14: IMP-011 | B14: BAT-011 | C14: =_xlfn.LET(_xlpm.d,_xlfn.XLOOKUP(B14,システム要求!$A$4:$A$113,システム要求!$D$4:$D$113,""),_xlpm.m,_xlfn.XLOOKUP(B14,システム要求!$A$4:$A$113,システム要求!$C$4:$C$113,""),IF(_xlpm.d<>"",IFERROR(_xlfn.TEXTBEFORE(_xlpm.d,"："),IFERROR(_xlfn.TEXTBEFORE(_xlpm.d,":"),_xlpm.d)),TRIM(B14&" "&_xlpm.m))) -> 法規(UN-R-100)を満足させる | D14: K-3 強度・衝突安全
A15: IMP-012 | B15: BAT-012 | C15: =_xlfn.LET(_xlpm.d,_xlfn.XLOOKUP(B15,システム要求!$A$4:$A$113,システム要求!$D$4:$D$113,""),_xlpm.m,_xlfn.XLOOKUP(B15,システム要求!$A$4:$A$113,システム要求!$C$4:$C$113,""),IF(_xlpm.d<>"",IFERROR(_xlfn.TEXTBEFORE(_xlpm.d,"："),IFERROR(_xlfn.TEXTBEFORE(_xlpm.d,":"),_xlpm.d)),TRIM(B15&" "&_xlpm.m))) -> 法規(SASO + GSO ECE 100)を満足させる | D15: 実働応力・悪路・高速波状路・突起乗り越し等の構造耐久
... A22: IMP-019 | B22: BAT-019 | C22: =_xlfn.LET(_xlpm.d,_xlfn.XLOOKUP(B22,システム要求!$A$4:$A$113,システム要求!$D$4:$D$113,""),_xlpm.m,_xlfn.XLOOKUP(B22,システム要求!$A$4:$A$113,システム要求!$C$4:$C$113,""),IF(_xlpm.d<>"",IFERROR(_xlfn.TEXTBEFORE(_xlpm.d,"："),IFERROR(_xlfn.TEXTBEFORE(_xlpm.d,":"),_xlpm.d)),TRIM(B22&" "&_xlpm.m))) -> BS25 冷却温度制御条件 | D22: 衝突時のエネルギー吸収量・セル保護判定
A23: IMP-021 | B23: BAT-020 | C23: =_xlfn.LET(_xlpm.d,_xlfn.XLOOKUP(B23,システム要求!$A$4:$A$113,システム要求!$D$4:$D$113,""),_xlpm.m,_xlfn.XLOOKUP(B23,システム要求!$A$4:$A$113,システム要求!$C$4:$C$113,""),IF(_xlpm.d<>"",IFERROR(_xlfn.TEXTBEFORE(_xlpm.d,"："),IFERROR(_xlfn.TEXTBEFORE(_xlpm.d,":"),_xlpm.d)),TRIM(B23&" "&_xlpm.m))) -> BS27 動作温度限界性能 | E23: EXT013 | F23: EXT011 | G23: EXT006
A24: IMP-022 | B24: BAT-021 | C24: =_xlfn.LET(_xlpm.d,_xlfn.XLOOKUP(B24,システム要求!$A$4:$A$113,システム要求!$D$4:$D$113,""),_xlpm.m,_xlfn.XLOOKUP(B24,システム要求!$A$4:$A$113,システム要求!$C$4:$C$113,""),IF(_xlpm.d<>"",IFERROR(_xlfn.TEXTBEFORE(_xlpm.d,"："),IFERROR(_xlfn.TEXTBEFORE(_xlpm.d,":"),_xlpm.d)),TRIM(B24&" "&_xlpm.m))) -> BS28 環境動作温度・湿度範囲 | E24: EXT013 | F24: EXT011 | G24: EXT006
A25: IMP-023 | B25: BAT-022 | C25: =_xlfn.LET(_xlpm.d,_xlfn.XLOOKUP(B25,システム要求!$A$4:$A$113,システム要求!$D$4:$D$113,""),_xlpm.m,_xlfn.XLOOKUP(B25,システム要求!$A$4:$A$113,システム要求!$C$4:$C$113,""),IF(_xlpm.d<>"",IFERROR(_xlfn.TEXTBEFORE(_xlpm.d,"："),IFERROR(_xlfn.TEXTBEFORE(_xlpm.d,":"),_xlpm.d)),TRIM(B25&" "&_xlpm.m))) -> K-3 強度・衝突安全 | E25: EXT013 | F25: EXT011 | G25: EXT006
A26: IMP-024 | B26: BAT-023 | C26: =_xlfn.LET(_xlpm.d,_xlfn.XLOOKUP(B26,システム要求!$A$4:$A$113,システム要求!$D$4:$D$113,""),_xlpm.m,_xlfn.XLOOKUP(B26,システム要求!$A$4:$A$113,システム要求!$C$4:$C$113,""),IF(_xlpm.d<>"",IFERROR(_xlfn.TEXTBEFORE(_xlpm.d,"："),IFERROR(_xlfn.TEXTBEFORE(_xlpm.d,":"),_xlpm.d)),TRIM(B26&" "&_xlpm.m))) -> BS11 耐久信頼性性能 | E26: EXT013 | F26: EXT011 | G26: EXT006
A27: IMP-025 | B27: BAT-024 | C27: =_xlfn.LET(_xlpm.d,_xlfn.XLOOKUP(B27,システム要求!$A$4:$A$113,システム要求!$D$4:$D$113,""),_xlpm.m,_xlfn.XLOOKUP(B27,システム要求!$A$4:$A$113,システム要求!$C$4:$C$113,""),IF(_xlpm.d<>"",IFERROR(_xlfn.TEXTBEFORE(_xlpm.d,"："),IFERROR(_xlfn.TEXTBEFORE(_xlpm.d,":"),_xlpm.d)),TRIM(B27&" "&_xlpm.m))) -> BS12 振動適合 | E27: EXT013 | F27: EXT011 | G27: EXT006
A28: IMP-026 | B28: BAT-025 | C28: =_xlfn.LET(_xlpm.d,_xlfn.XLOOKUP(B28,システム要求!$A$4:$A$113,システム要求!$D$4:$D$113,""),_xlpm.m,_xlfn.XLOOKUP(B28,システム要求!$A$4:$A$113,システム要求!$C$4:$C$113,""),IF(_xlpm.d<>"",IFERROR(_xlfn.TEXTBEFORE(_xlpm.d,"："),IFERROR(_xlfn.TEXTBEFORE(_xlpm.d,":"),_xlpm.d)),TRIM(B28&" "&_xlpm.m))) -> BS16 圧壊安全性性能 | E28: EXT013 | F28: EXT011 | G28: EXT006
A29: IMP-027 | B29: BAT-026 | C29: =_xlfn.LET(_xlpm.d,_xlfn.XLOOKUP(B29,システム要求!$A$4:$A$113,システム要求!$D$4:$D$113,""),_xlpm.m,_xlfn.XLOOKUP(B29,システム要求!$A$4:$A$113,システム要求!$C$4:$C$113,""),IF(_xlpm.d<>"",IFERROR(_xlfn.TEXTBEFORE(_xlpm.d,"："),IFERROR(_xlfn.TEXTBEFORE(_xlpm.d,":"),_xlpm.d)),TRIM(B29&" "&_xlpm.m))) -> BS14 路面・落下物干渉防護 | E29: EXT013 | F29: EXT011 | G29: EXT006
A30: IMP-036 | B30: BAT-027 | C30: =_xlfn.LET(_xlpm.d,_xlfn.XLOOKUP(B30,システム要求!$A$4:$A$113,システム要求!$D$4:$D$113,""),_xlpm.m,_xlfn.XLOOKUP(B30,システム要求!$A$4:$A$113,システム要求!$C$4:$C$113,""),IF(_xlpm.d<>"",IFERROR(_xlfn.TEXTBEFORE(_xlpm.d,"："),IFERROR(_xlfn.TEXTBEFORE(_xlpm.d,":"),_xlpm.d)),TRIM(B30&" "&_xlpm.m))) -> BS19 底部機械防護性能 | D30: 排煙センサにて異常検知できること
A31: IMP-037 | B31: BAT-028 | C31: =_xlfn.LET(_xlpm.d,_xlfn.XLOOKUP(B31,システム要求!$A$4:$A$113,システム要求!$D$4:$D$113,""),_xlpm.m,_xlfn.XLOOKUP(B31,システム要求!$A$4:$A$113,システム要求!$C$4:$C$113,""),IF(_xlpm.d<>"",IFERROR(_xlfn.TEXTBEFORE(_xlpm.d,"："),IFERROR(_xlfn.TEXTBEFORE(_xlpm.d,":"),_xlpm.d)),TRIM(B31&" "&_xlpm.m))) -> BAT-028 側突 | D31: パックシール性能
A32: IMP-038 | B32: BAT-029 | C32: =_xlfn.LET(_xlpm.d,_xlfn.XLOOKUP(B32,システム要求!$A$4:$A$113,システム要求!$D$4:$D$113,""),_xlpm.m,_xlfn.XLOOKUP(B32,システム要求!$A$4:$A$113,システム要求!$C$4:$C$113,""),IF(_xlpm.d<>"",IFERROR(_xlfn.TEXTBEFORE(_xlpm.d,"："),IFERROR(_xlfn.TEXTBEFORE(_xlpm.d,":"),_xlpm.d)),TRIM(B32&" "&_xlpm.m))) -> BAT-029 ポール側突 | D32: 外部浸水に対する防護レベル（IPX7等）
A33: IMP-039 | B33: BAT-030 | C33: =_xlfn.LET(_xlpm.d,_xlfn.XLOOKUP(B33,システム要求!$A$4:$A$113,システム要求!$D$4:$D$113,""),_xlpm.m,_xlfn.XLOOKUP(B33,システム要求!$A$4:$A$113,システム要求!$C$4:$C$113,""),IF(_xlpm.d<>"",IFERROR(_xlfn.TEXTBEFORE(_xlpm.d,"："),IFERROR(_xlfn.TEXTBEFORE(_xlpm.d,":"),_xlpm.d)),TRIM(B33&" "&_xlpm.m))) -> BS15 衝突安全性性能 | D33: パック内部浸水の即時検知機能
A34: IMP-040 | B34: BAT-031 | C34: =_xlfn.LET(_xlpm.d,_xlfn.XLOOKUP(B34,システム要求!$A$4:$A$113,システム要求!$D$4:$D$113,""),_xlpm.m,_xlfn.XLOOKUP(B34,システム要求!$A$4:$A$113,システム要求!$C$4:$C$113,""),IF(_xlpm.d<>"",IFERROR(_xlfn.TEXTBEFORE(_xlpm.d,"："),IFERROR(_xlfn.TEXTBEFORE(_xlpm.d,":"),_xlpm.d)),TRIM(B34&" "&_xlpm.m))) -> 法規(UN-R-100/05)を満足させる | D34: 内外気圧差調停と高気密維持
A35: IMP-041 | B35: BAT-032 | C35: =_xlfn.LET(_xlpm.d,_xlfn.XLOOKUP(B35,システム要求!$A$4:$A$113,システム要求!$D$4:$D$113,""),_xlpm.m,_xlfn.XLOOKUP(B35,システム要求!$A$4:$A$113,システム要求!$C$4:$C$113,""),IF(_xlpm.d<>"",IFERROR(_xlfn.TEXTBEFORE(_xlpm.d,"："),IFERROR(_xlfn.TEXTBEFORE(_xlpm.d,":"),_xlpm.d)),TRIM(B35&" "&_xlpm.m))) -> 法規(UN-R-100/05)を満足させる | D35: 結露耐性
A36: IMP-042 | B36: BAT-033 | C36: =_xlfn.LET(_xlpm.d,_xlfn.XLOOKUP(B36,システム要求!$A$4:$A$113,システム要求!$D$4:$D$113,""),_xlpm.m,_xlfn.XLOOKUP(B36,システム要求!$A$4:$A$113,システム要求!$C$4:$C$113,""),IF(_xlpm.d<>"",IFERROR(_xlfn.TEXTBEFORE(_xlpm.d,"："),IFERROR(_xlfn.TEXTBEFORE(_xlpm.d,":"),_xlpm.d)),TRIM(B36&" "&_xlpm.m))) -> 法規(UN-R-100/05)を満足させる | D36: 各国の使用環境や法規への適合
A37: IMP-043 | B37: BAT-034 | C37: =_xlfn.LET(_xlpm.d,_xlfn.XLOOKUP(B37,システム要求!$A$4:$A$113,システム要求!$D$4:$D$113,""),_xlpm.m,_xlfn.XLOOKUP(B37,システム要求!$A$4:$A$113,システム要求!$C$4:$C$113,""),IF(_xlpm.d<>"",IFERROR(_xlfn.TEXTBEFORE(_xlpm.d,"："),IFERROR(_xlfn.TEXTBEFORE(_xlpm.d,":"),_xlpm.d)),TRIM(B37&" "&_xlpm.m))) -> 法規(UN-R-100/05)を満足させる | D37: 有害物質（RoHS/REACH等）の排除
A38: IMP-044 | B38: BAT-035 | C38: =_xlfn.LET(_xlpm.d,_xlfn.XLOOKUP(B38,システム要求!$A$4:$A$113,システム要求!$D$4:$D$113,""),_xlpm.m,_xlfn.XLOOKUP(B38,システム要求!$A$4:$A$113,システム要求!$C$4:$C$113,""),IF(_xlpm.d<>"",IFERROR(_xlfn.TEXTBEFORE(_xlpm.d,"："),IFERROR(_xlfn.TEXTBEFORE(_xlpm.d,":"),_xlpm.d)),TRIM(B38&" "&_xlpm.m))) -> 法規(GB38031-2025)を満足させる | D38: 難燃基準・車室内VOC基準適合
A39: IMP-045 | B39: BAT-036 | C39: =_xlfn.LET(_xlpm.d,_xlfn.XLOOKUP(B39,システム要求!$A$4:$A$113,システム要求!$D$4:$D$113,""),_xlpm.m,_xlfn.XLOOKUP(B39,システム要求!$A$4:$A$113,システム要求!$C$4:$C$113,""),IF(_xlpm.d<>"",IFERROR(_xlfn.TEXTBEFORE(_xlpm.d,"："),IFERROR(_xlfn.TEXTBEFORE(_xlpm.d,":"),_xlpm.d)),TRIM(B39&" "&_xlpm.m))) -> 法規(GB38031-2025)を満足させる | D39: 廃車時の解体容易性・素材識別性
A40: IMP-046 | B40: BAT-037 | C40: =_xlfn.LET(_xlpm.d,_xlfn.XLOOKUP(B40,システム要求!$A$4:$A$113,システム要求!$D$4:$D$113,""),_xlpm.m,_xlfn.XLOOKUP(B40,システム要求!$A$4:$A$113,システム要求!$C$4:$C$113,""),IF(_xlpm.d<>"",IFERROR(_xlfn.TEXTBEFORE(_xlpm.d,"："),IFERROR(_xlfn.TEXTBEFORE(_xlpm.d,":"),_xlpm.d)),TRIM(B40&" "&_xlpm.m))) -> 法規(GB38031-2025)を満足させる | D40: 耐熱・耐火性能
A41: IMP-047 | B41: BAT-038 | C41: =_xlfn.LET(_xlpm.d,_xlfn.XLOOKUP(B41,システム要求!$A$4:$A$113,システム要求!$D$4:$D$113,""),_xlpm.m,_xlfn.XLOOKUP(B41,システム要求!$A$4:$A$113,システム要求!$C$4:$C$113,""),IF(_xlpm.d<>"",IFERROR(_xlfn.TEXTBEFORE(_xlpm.d,"："),IFERROR(_xlfn.TEXTBEFORE(_xlpm.d,":"),_xlpm.d)),TRIM(B41&" "&_xlpm.m))) -> 法規(FMVSS305a/Part561)を満足させる | D41: 絶縁・シール信頼性
... A65: IMP-071 | B65: BAT-062 | C65: =_xlfn.LET(_xlpm.d,_xlfn.XLOOKUP(B65,システム要求!$A$4:$A$113,システム要求!$D$4:$D$113,""),_xlpm.m,_xlfn.XLOOKUP(B65,システム要求!$A$4:$A$113,システム要求!$C$4:$C$113,""),IF(_xlpm.d<>"",IFERROR(_xlfn.TEXTBEFORE(_xlpm.d,"："),IFERROR(_xlfn.TEXTBEFORE(_xlpm.d,":"),_xlpm.d)),TRIM(B65&" "&_xlpm.m))) -> BS07 寿命 | D65: 製造ラインでの組みやすさ・分解メンテ安全

Sheet 他システム
B1: 外部システム
B2: 【外部システム：車両内（電気・制御）】
A3: EXT001 | B3: 高電圧配電系（ジャンクションボックス・高圧ハーネス）
A4: EXT002 | B4: PCU／インバータ・駆動モータ（電動パワートレーン）
A5: EXT003 | B5: DC-DCコンバータ・補機12V電源系
A6: EXT004 | B6: 車載充電器（OBC）／充電インレット・充電制御
A7: EXT005 | B7: 外部急速充電設備インタフェース（CHAdeMO／CCS／GB/T）
A8: EXT006 | B8: BMS上位：車両制御ECU（VCU／HV-ECU）
A9: EXT007 | B9: 車載ネットワーク（CAN／CAN-FD／Ethernet）
A10: EXT008 | B10: 電源遮断・サービスプラグ／メインリレー系
A11: EXT009 | B11: 衝突検知・エアバッグECU（衝突時高電圧遮断）
A12: EXT010 | B12: 絶縁抵抗監視（漏電検知）システム
B13: 【外部システム：車両内（熱・機械）】
A14: EXT011 | B14: 電池冷却／熱管理システム（クーラント回路・チラー・ヒータ）
A15: EXT012 | B15: 空調（HVAC）システム・乗員室換気
A16: EXT013 | B16: 車体骨格・フロア構造／サイドメンバ（側突・ポール側突）
A17: EXT014 | B17: サスペンション・車両運動（振動・悪路入力）
A18: EXT015 | B18: アンダーカバー／床下防護構造（路面干渉・落下物）
A19: EXT016 | B19: 排煙・ベントダクト（熱暴走ガス排出経路）
A20: EXT017 | B20: 消火／熱拡散抑制デバイス
B21: 【外部システム：車両外・オフボード】
A22: EXT018 | B22: 警報・HMI（メータ表示・警報音）／乗員通知
A23: EXT019 | B23: テレマティクス・コネクテッドサービス（遠隔監視・OTA）
A24: EXT020 | B24: 充電インフラ・電力系統／V2G・V2H
A25: EXT021 | B25: 診断ツール・サービスツール（故障診断／整備）
A26: EXT022 | B26: 生産設備・組立ライン／物流（輸送・保管）
A27: EXT023 | B27: リユース・リサイクル・廃棄システム
B28: 【ステークホルダー】
A29: EXT024 | B29: ユーザ／ドライバ・乗員
A30: EXT025 | B30: 整備・サービス事業者（ディーラ）
A31: EXT026 | B31: 救助隊・消防・レスキュー（第一対応者）
A32: EXT027 | B32: 法規当局・認証機関（UN-R100/05、GB38031、FMVSS305a/Part561）
A33: EXT028 | B33: 試験・認証機関（型式認証、NCAP等）
A34: EXT029 | B34: セルメーカ・電池サプライヤ
A35: EXT030 | B35: 部品サプライヤ（熱伝導材・断熱材・筐体・電装部品）
A36: EXT031 | B36: 車両開発部門（車体・シャシ・電子・熱・安全性能）
A37: EXT032 | B37: 電池パック開発・機能主査（熱拡散・強度・電気安全）
A38: EXT033 | B38: 生産技術・製造部門
A39: EXT034 | B39: 品質保証・信頼性部門
A40: EXT035 | B40: 物流・輸送事業者（危険物輸送規制対応）
...

Sheet 類似ID抽出
A1: C列 類似要求ID 抽出結果
A2: 対象：`熱拡散防止サブシステム要求` の A列ID と C列「ステークホルダーニーズ/システム機能」。同一IDが複数グループに出る場合は、複数観点で類似していることを示します。
A4: 類似グループID | B4: 類似度 | C4: 類似テーマ | D4: 該当ID（A列） | E4: 件数 | F4: 代表的なC列記載 | G4: 判定理由・共通語
A5: G01 | B5: 完全一致 | C5: デブリ・溶融金属によるブリッジ（短絡）防止 | D5: BATs-003, BATs-004 | E5: 2 | F5: デブリ・溶融金属によるブリッジ（短絡）を防止する | G5: C列文言が完全一致
A6: G02 | B6: 完全一致 | C6: 排煙空間（余剰体積）確保による圧力上昇防止 | D6: BATs-048, BATs-051 | E6: 2 | F6: 排煙空間（余剰体積）を十分に確保すること（余剰体積不足による圧力上昇を防ぐ） | G6: C列文言が完全一致
A7: G03 | B7: 高 | C7: シール部・シール材の破綻／溶損防止 | D7: BATs-001, BATs-017, BATs-023, BATs-025, BATs-026, BATs-027 | E7: 6 | F7: 合わせ面からの漏煙を防止する／パックシール部温度・圧力を抑制し、シールが溶損しないこと | G7: シール、漏煙、溶損、破綻、耐圧、耐熱、温度・圧力の抑制が共通
A8: G04 | B8: 高 | C8: 排煙口・排煙方向と点火源の分離 | D8: BATs-019, BATs-020, BATs-021, BATs-022 | E8: 4 | F8: 排煙口と点火源が十分に離れた配置とすること／排煙方向に点火源が存在しないレイアウトとすること | G8: 排煙、点火源、距離、方向、流速、配置分離が共通
A9: G05 | B9: 高 | C9: 排煙バルブ／呼吸膜の配置・耐圧・耐熱 | D9: BATs-010, BATs-011, BATs-012, BATs-033, BATs-034, BATs-035, BATs-036, BATs-037 | E9: 8 | F9: 排煙弁と呼吸膜を同一方向に配置／排煙バルブが想定内圧・想定温度に耐える | G9: 排煙バルブ、呼吸膜、内圧、温度、配置の要求が共通
A10: G06 | B10: 高 | C10: 酸素流入・酸素濃度管理による発火／自己着火防止 | D10: BATs-010, BATs-011, BATs-061 | E10: 3 | F10: パック内への酸素流入によるガス発火を防止／酸素濃度を自己着火に至らない水準に管理 | G10: 酸素流入、酸素濃度、発火・自己着火抑制が共通
